
2025-02-21 11:41:32,953 INFO: errors [in /Users/Ricardo/Documents/Software Development/Fy-yur/app.py:506]
2025-02-21 12:02:24,958 INFO: errors [in /Users/Ricardo/Documents/Software Development/Fy-yur/app.py:517]
2025-02-21 12:58:36,048 INFO: errors [in /Users/Ricardo/Documents/Software Development/Fy-yur/app.py:497]
2025-02-21 12:59:05,132 INFO: errors [in /Users/Ricardo/Documents/Software Development/Fy-yur/app.py:497]
2025-02-21 12:59:18,372 INFO: errors [in /Users/Ricardo/Documents/Software Development/Fy-yur/app.py:497]
2025-02-23 20:50:19,533 INFO: errors [in /Users/Ricardo/Documents/Software Development/Fy-yur/app.py:514]
2025-02-23 20:51:20,919 INFO: errors [in /Users/Ricardo/Documents/Software Development/Fy-yur/app.py:514]
2025-02-24 08:20:14,391 INFO: errors [in /Users/Ricardo/Documents/Software Development/Fy-yur/app.py:500]
2025-02-24 08:20:43,841 INFO: errors [in /Users/Ricardo/Documents/Software Development/Fy-yur/app.py:500]
2025-02-24 08:21:30,245 INFO: errors [in /Users/Ricardo/Documents/Software Development/Fy-yur/app.py:500]
2025-02-24 08:22:06,335 INFO: errors [in /Users/Ricardo/Documents/Software Development/Fy-yur/app.py:500]
2025-02-24 08:53:05,717 INFO: errors [in /Users/Ricardo/Documents/Software Development/Fy-yur/app.py:470]
2025-02-24 08:54:53,250 ERROR: Exception on /venues/1 [GET] [in /Users/Ricardo/.pyenv/versions/3.8.20/lib/python3.8/site-packages/flask/app.py:838]
Traceback (most recent call last):
  File "/Users/Ricardo/.pyenv/versions/3.8.20/lib/python3.8/site-packages/flask/app.py", line 1473, in wsgi_app
    response = self.full_dispatch_request()
  File "/Users/Ricardo/.pyenv/versions/3.8.20/lib/python3.8/site-packages/flask/app.py", line 882, in full_dispatch_request
    rv = self.handle_user_exception(e)
  File "/Users/Ricardo/.pyenv/versions/3.8.20/lib/python3.8/site-packages/flask/app.py", line 880, in full_dispatch_request
    rv = self.dispatch_request()
  File "/Users/Ricardo/.pyenv/versions/3.8.20/lib/python3.8/site-packages/flask/app.py", line 865, in dispatch_request
    return self.ensure_sync(self.view_functions[rule.endpoint])(**view_args)  # type: ignore[no-any-return]
  File "/Users/Ricardo/Documents/Software Development/Fy-yur/app.py", line 148, in show_venue
    show_rel = db.session.query(shows).filter_by(venue_id=venue.id, artist_id=artist.id).first()
  File "/Users/Ricardo/.pyenv/versions/3.8.20/lib/python3.8/site-packages/sqlalchemy/orm/scoping.py", line 1681, in query
    return self._proxied.query(*entities, **kwargs)
  File "/Users/Ricardo/.pyenv/versions/3.8.20/lib/python3.8/site-packages/sqlalchemy/orm/session.py", line 2955, in query
    return self._query_cls(entities, self, **kwargs)
  File "/Users/Ricardo/.pyenv/versions/3.8.20/lib/python3.8/site-packages/sqlalchemy/orm/query.py", line 275, in __init__
    self._set_entities(entities)
  File "/Users/Ricardo/.pyenv/versions/3.8.20/lib/python3.8/site-packages/sqlalchemy/orm/query.py", line 287, in _set_entities
    self._raw_columns = [
  File "/Users/Ricardo/.pyenv/versions/3.8.20/lib/python3.8/site-packages/sqlalchemy/orm/query.py", line 288, in <listcomp>
    coercions.expect(
  File "/Users/Ricardo/.pyenv/versions/3.8.20/lib/python3.8/site-packages/sqlalchemy/sql/coercions.py", line 332, in expect
    return lambdas.LambdaElement(
  File "/Users/Ricardo/.pyenv/versions/3.8.20/lib/python3.8/site-packages/sqlalchemy/sql/lambdas.py", line 213, in __init__
    rec = self._retrieve_tracker_rec(fn, apply_propagate_attrs, opts)
  File "/Users/Ricardo/.pyenv/versions/3.8.20/lib/python3.8/site-packages/sqlalchemy/sql/lambdas.py", line 229, in _retrieve_tracker_rec
    tracker = AnalyzedCode.get(
  File "/Users/Ricardo/.pyenv/versions/3.8.20/lib/python3.8/site-packages/sqlalchemy/sql/lambdas.py", line 753, in get
    cls._fns[fn.__code__] = analyzed = AnalyzedCode(
  File "/Users/Ricardo/.pyenv/versions/3.8.20/lib/python3.8/site-packages/sqlalchemy/sql/lambdas.py", line 795, in __init__
    self._setup_additional_closure_trackers(fn, lambda_element, opts)
  File "/Users/Ricardo/.pyenv/versions/3.8.20/lib/python3.8/site-packages/sqlalchemy/sql/lambdas.py", line 863, in _setup_additional_closure_trackers
    analyzed_function = AnalyzedFunction(
  File "/Users/Ricardo/.pyenv/versions/3.8.20/lib/python3.8/site-packages/sqlalchemy/sql/lambdas.py", line 1129, in __init__
    self._instrument_and_run_function(lambda_element)
  File "/Users/Ricardo/.pyenv/versions/3.8.20/lib/python3.8/site-packages/sqlalchemy/sql/lambdas.py", line 1199, in _instrument_and_run_function
    self.expr = lambda_element._invoke_user_fn(tracker_instrumented_fn)
  File "/Users/Ricardo/.pyenv/versions/3.8.20/lib/python3.8/site-packages/sqlalchemy/sql/lambdas.py", line 425, in _invoke_user_fn
    return fn()  # type: ignore[no-any-return]
  File "/Users/Ricardo/Documents/Software Development/Fy-yur/app.py", line 407, in shows
    shows_in_db = db.session.execute(select(show)).fetchall()
  File "/Users/Ricardo/.pyenv/versions/3.8.20/lib/python3.8/site-packages/sqlalchemy/sql/lambdas.py", line 1329, in __call__
    raise exc.InvalidRequestError(
sqlalchemy.exc.InvalidRequestError: Can't invoke Python callable execute() inside of lambda expression argument at <code object shows at 0x1022dc710, file "/Users/Ricardo/Documents/Software Development/Fy-yur/app.py", line 404>; lambda SQL constructs should not invoke functions from closure variables to produce literal values since the lambda SQL system normally extracts bound values without actually invoking the lambda or any functions within it.  Call the function outside of the lambda and assign to a local variable that is used in the lambda as a closure variable, or set track_bound_values=False if the return value of this function is used in some other way other than a SQL bound value.
2025-02-24 08:55:48,265 ERROR: Exception on /venues/1 [GET] [in /Users/Ricardo/.pyenv/versions/3.8.20/lib/python3.8/site-packages/flask/app.py:838]
Traceback (most recent call last):
  File "/Users/Ricardo/.pyenv/versions/3.8.20/lib/python3.8/site-packages/flask/app.py", line 1473, in wsgi_app
    response = self.full_dispatch_request()
  File "/Users/Ricardo/.pyenv/versions/3.8.20/lib/python3.8/site-packages/flask/app.py", line 882, in full_dispatch_request
    rv = self.handle_user_exception(e)
  File "/Users/Ricardo/.pyenv/versions/3.8.20/lib/python3.8/site-packages/flask/app.py", line 880, in full_dispatch_request
    rv = self.dispatch_request()
  File "/Users/Ricardo/.pyenv/versions/3.8.20/lib/python3.8/site-packages/flask/app.py", line 865, in dispatch_request
    return self.ensure_sync(self.view_functions[rule.endpoint])(**view_args)  # type: ignore[no-any-return]
  File "/Users/Ricardo/Documents/Software Development/Fy-yur/app.py", line 148, in show_venue
    show_rel = db.session.query(shows).filter_by(venue_id=venue.id, artist_id=artist.id).first()
  File "/Users/Ricardo/.pyenv/versions/3.8.20/lib/python3.8/site-packages/sqlalchemy/orm/scoping.py", line 1681, in query
    return self._proxied.query(*entities, **kwargs)
  File "/Users/Ricardo/.pyenv/versions/3.8.20/lib/python3.8/site-packages/sqlalchemy/orm/session.py", line 2955, in query
    return self._query_cls(entities, self, **kwargs)
  File "/Users/Ricardo/.pyenv/versions/3.8.20/lib/python3.8/site-packages/sqlalchemy/orm/query.py", line 275, in __init__
    self._set_entities(entities)
  File "/Users/Ricardo/.pyenv/versions/3.8.20/lib/python3.8/site-packages/sqlalchemy/orm/query.py", line 287, in _set_entities
    self._raw_columns = [
  File "/Users/Ricardo/.pyenv/versions/3.8.20/lib/python3.8/site-packages/sqlalchemy/orm/query.py", line 288, in <listcomp>
    coercions.expect(
  File "/Users/Ricardo/.pyenv/versions/3.8.20/lib/python3.8/site-packages/sqlalchemy/sql/coercions.py", line 332, in expect
    return lambdas.LambdaElement(
  File "/Users/Ricardo/.pyenv/versions/3.8.20/lib/python3.8/site-packages/sqlalchemy/sql/lambdas.py", line 213, in __init__
    rec = self._retrieve_tracker_rec(fn, apply_propagate_attrs, opts)
  File "/Users/Ricardo/.pyenv/versions/3.8.20/lib/python3.8/site-packages/sqlalchemy/sql/lambdas.py", line 229, in _retrieve_tracker_rec
    tracker = AnalyzedCode.get(
  File "/Users/Ricardo/.pyenv/versions/3.8.20/lib/python3.8/site-packages/sqlalchemy/sql/lambdas.py", line 753, in get
    cls._fns[fn.__code__] = analyzed = AnalyzedCode(
  File "/Users/Ricardo/.pyenv/versions/3.8.20/lib/python3.8/site-packages/sqlalchemy/sql/lambdas.py", line 795, in __init__
    self._setup_additional_closure_trackers(fn, lambda_element, opts)
  File "/Users/Ricardo/.pyenv/versions/3.8.20/lib/python3.8/site-packages/sqlalchemy/sql/lambdas.py", line 863, in _setup_additional_closure_trackers
    analyzed_function = AnalyzedFunction(
  File "/Users/Ricardo/.pyenv/versions/3.8.20/lib/python3.8/site-packages/sqlalchemy/sql/lambdas.py", line 1129, in __init__
    self._instrument_and_run_function(lambda_element)
  File "/Users/Ricardo/.pyenv/versions/3.8.20/lib/python3.8/site-packages/sqlalchemy/sql/lambdas.py", line 1199, in _instrument_and_run_function
    self.expr = lambda_element._invoke_user_fn(tracker_instrumented_fn)
  File "/Users/Ricardo/.pyenv/versions/3.8.20/lib/python3.8/site-packages/sqlalchemy/sql/lambdas.py", line 425, in _invoke_user_fn
    return fn()  # type: ignore[no-any-return]
  File "/Users/Ricardo/Documents/Software Development/Fy-yur/app.py", line 407, in shows
    shows_in_db = db.session.execute(select(show)).fetchall()
  File "/Users/Ricardo/.pyenv/versions/3.8.20/lib/python3.8/site-packages/sqlalchemy/sql/lambdas.py", line 1329, in __call__
    raise exc.InvalidRequestError(
sqlalchemy.exc.InvalidRequestError: Can't invoke Python callable execute() inside of lambda expression argument at <code object shows at 0x1022dc710, file "/Users/Ricardo/Documents/Software Development/Fy-yur/app.py", line 404>; lambda SQL constructs should not invoke functions from closure variables to produce literal values since the lambda SQL system normally extracts bound values without actually invoking the lambda or any functions within it.  Call the function outside of the lambda and assign to a local variable that is used in the lambda as a closure variable, or set track_bound_values=False if the return value of this function is used in some other way other than a SQL bound value.
2025-02-24 08:57:25,339 INFO: errors [in /Users/Ricardo/Documents/Software Development/Fy-yur/app.py:470]
2025-02-24 09:10:26,069 ERROR: Exception on /artists/1 [GET] [in /Users/Ricardo/.pyenv/versions/3.8.20/lib/python3.8/site-packages/flask/app.py:838]
Traceback (most recent call last):
  File "/Users/Ricardo/.pyenv/versions/3.8.20/lib/python3.8/site-packages/flask/app.py", line 1473, in wsgi_app
    response = self.full_dispatch_request()
  File "/Users/Ricardo/.pyenv/versions/3.8.20/lib/python3.8/site-packages/flask/app.py", line 882, in full_dispatch_request
    rv = self.handle_user_exception(e)
  File "/Users/Ricardo/.pyenv/versions/3.8.20/lib/python3.8/site-packages/flask/app.py", line 880, in full_dispatch_request
    rv = self.dispatch_request()
  File "/Users/Ricardo/.pyenv/versions/3.8.20/lib/python3.8/site-packages/flask/app.py", line 865, in dispatch_request
    return self.ensure_sync(self.view_functions[rule.endpoint])(**view_args)  # type: ignore[no-any-return]
  File "/Users/Ricardo/Documents/Software Development/Fy-yur/app.py", line 325, in show_artist
    data = list(filter(lambda d: d['id'] == artist_id, [data1, data2, data3]))[0]
IndexError: list index out of range
2025-02-24 09:10:33,794 ERROR: Exception on /artists/2 [GET] [in /Users/Ricardo/.pyenv/versions/3.8.20/lib/python3.8/site-packages/flask/app.py:838]
Traceback (most recent call last):
  File "/Users/Ricardo/.pyenv/versions/3.8.20/lib/python3.8/site-packages/flask/app.py", line 1473, in wsgi_app
    response = self.full_dispatch_request()
  File "/Users/Ricardo/.pyenv/versions/3.8.20/lib/python3.8/site-packages/flask/app.py", line 882, in full_dispatch_request
    rv = self.handle_user_exception(e)
  File "/Users/Ricardo/.pyenv/versions/3.8.20/lib/python3.8/site-packages/flask/app.py", line 880, in full_dispatch_request
    rv = self.dispatch_request()
  File "/Users/Ricardo/.pyenv/versions/3.8.20/lib/python3.8/site-packages/flask/app.py", line 865, in dispatch_request
    return self.ensure_sync(self.view_functions[rule.endpoint])(**view_args)  # type: ignore[no-any-return]
  File "/Users/Ricardo/Documents/Software Development/Fy-yur/app.py", line 325, in show_artist
    data = list(filter(lambda d: d['id'] == artist_id, [data1, data2, data3]))[0]
IndexError: list index out of range
2025-02-24 09:10:40,191 ERROR: Exception on /artists/1 [GET] [in /Users/Ricardo/.pyenv/versions/3.8.20/lib/python3.8/site-packages/flask/app.py:838]
Traceback (most recent call last):
  File "/Users/Ricardo/.pyenv/versions/3.8.20/lib/python3.8/site-packages/flask/app.py", line 1473, in wsgi_app
    response = self.full_dispatch_request()
  File "/Users/Ricardo/.pyenv/versions/3.8.20/lib/python3.8/site-packages/flask/app.py", line 882, in full_dispatch_request
    rv = self.handle_user_exception(e)
  File "/Users/Ricardo/.pyenv/versions/3.8.20/lib/python3.8/site-packages/flask/app.py", line 880, in full_dispatch_request
    rv = self.dispatch_request()
  File "/Users/Ricardo/.pyenv/versions/3.8.20/lib/python3.8/site-packages/flask/app.py", line 865, in dispatch_request
    return self.ensure_sync(self.view_functions[rule.endpoint])(**view_args)  # type: ignore[no-any-return]
  File "/Users/Ricardo/Documents/Software Development/Fy-yur/app.py", line 325, in show_artist
    data = list(filter(lambda d: d['id'] == artist_id, [data1, data2, data3]))[0]
IndexError: list index out of range
2025-02-24 09:19:36,762 INFO: errors [in /Users/Ricardo/Documents/Software Development/Fy-yur/app.py:468]
2025-02-24 09:19:43,698 INFO: errors [in /Users/Ricardo/Documents/Software Development/Fy-yur/app.py:468]
2025-02-24 09:20:56,194 INFO: errors [in /Users/Ricardo/Documents/Software Development/Fy-yur/app.py:468]
2025-02-24 09:21:43,451 INFO: errors [in /Users/Ricardo/Documents/Software Development/Fy-yur/app.py:468]
2025-02-24 09:21:56,848 INFO: errors [in /Users/Ricardo/Documents/Software Development/Fy-yur/app.py:468]
2025-02-24 09:22:00,829 INFO: errors [in /Users/Ricardo/Documents/Software Development/Fy-yur/app.py:468]
2025-02-24 09:22:08,383 INFO: errors [in /Users/Ricardo/Documents/Software Development/Fy-yur/app.py:468]
2025-02-24 09:22:33,311 INFO: errors [in /Users/Ricardo/Documents/Software Development/Fy-yur/app.py:468]
2025-02-24 09:22:39,953 INFO: errors [in /Users/Ricardo/Documents/Software Development/Fy-yur/app.py:468]
2025-02-24 09:27:29,483 INFO: errors [in /Users/Ricardo/Documents/Software Development/Fy-yur/app.py:468]
2025-02-24 09:35:26,259 ERROR: Exception on /artists/3 [GET] [in /Users/Ricardo/.pyenv/versions/3.8.20/lib/python3.8/site-packages/flask/app.py:838]
Traceback (most recent call last):
  File "/Users/Ricardo/.pyenv/versions/3.8.20/lib/python3.8/site-packages/flask/app.py", line 1473, in wsgi_app
    response = self.full_dispatch_request()
  File "/Users/Ricardo/.pyenv/versions/3.8.20/lib/python3.8/site-packages/flask/app.py", line 882, in full_dispatch_request
    rv = self.handle_user_exception(e)
  File "/Users/Ricardo/.pyenv/versions/3.8.20/lib/python3.8/site-packages/flask/app.py", line 880, in full_dispatch_request
    rv = self.dispatch_request()
  File "/Users/Ricardo/.pyenv/versions/3.8.20/lib/python3.8/site-packages/flask/app.py", line 865, in dispatch_request
    return self.ensure_sync(self.view_functions[rule.endpoint])(**view_args)  # type: ignore[no-any-return]
  File "/Users/Ricardo/Documents/Software Development/Fy-yur/app.py", line 325, in show_artist
IndexError: list index out of range
2025-02-24 09:55:16,491 INFO: errors [in /Users/Ricardo/Documents/Software Development/Fy-yur/app.py:440]
2025-02-24 09:58:36,840 INFO: errors [in /Users/Ricardo/Documents/Software Development/Fy-yur/app.py:440]
2025-02-24 09:58:42,739 ERROR: Exception on /artists/3 [GET] [in /Users/Ricardo/.pyenv/versions/3.8.20/lib/python3.8/site-packages/flask/app.py:838]
Traceback (most recent call last):
  File "/Users/Ricardo/.pyenv/versions/3.8.20/lib/python3.8/site-packages/flask/app.py", line 1473, in wsgi_app
    response = self.full_dispatch_request()
  File "/Users/Ricardo/.pyenv/versions/3.8.20/lib/python3.8/site-packages/flask/app.py", line 882, in full_dispatch_request
    rv = self.handle_user_exception(e)
  File "/Users/Ricardo/.pyenv/versions/3.8.20/lib/python3.8/site-packages/flask/app.py", line 880, in full_dispatch_request
    rv = self.dispatch_request()
  File "/Users/Ricardo/.pyenv/versions/3.8.20/lib/python3.8/site-packages/flask/app.py", line 865, in dispatch_request
    return self.ensure_sync(self.view_functions[rule.endpoint])(**view_args)  # type: ignore[no-any-return]
  File "/Users/Ricardo/Documents/Software Development/Fy-yur/app.py", line 295, in show_artist
    data = list(filter(lambda d: d['id'] == artist_id, data))[0]
IndexError: list index out of range
2025-02-24 09:59:04,675 ERROR: Exception on /artists/4 [GET] [in /Users/Ricardo/.pyenv/versions/3.8.20/lib/python3.8/site-packages/flask/app.py:838]
Traceback (most recent call last):
  File "/Users/Ricardo/.pyenv/versions/3.8.20/lib/python3.8/site-packages/flask/app.py", line 1473, in wsgi_app
    response = self.full_dispatch_request()
  File "/Users/Ricardo/.pyenv/versions/3.8.20/lib/python3.8/site-packages/flask/app.py", line 882, in full_dispatch_request
    rv = self.handle_user_exception(e)
  File "/Users/Ricardo/.pyenv/versions/3.8.20/lib/python3.8/site-packages/flask/app.py", line 880, in full_dispatch_request
    rv = self.dispatch_request()
  File "/Users/Ricardo/.pyenv/versions/3.8.20/lib/python3.8/site-packages/flask/app.py", line 865, in dispatch_request
    return self.ensure_sync(self.view_functions[rule.endpoint])(**view_args)  # type: ignore[no-any-return]
  File "/Users/Ricardo/Documents/Software Development/Fy-yur/app.py", line 295, in show_artist
    data = list(filter(lambda d: d['id'] == artist_id, data))[0]
IndexError: list index out of range
2025-02-24 09:59:08,076 ERROR: Exception on /artists/3 [GET] [in /Users/Ricardo/.pyenv/versions/3.8.20/lib/python3.8/site-packages/flask/app.py:838]
Traceback (most recent call last):
  File "/Users/Ricardo/.pyenv/versions/3.8.20/lib/python3.8/site-packages/flask/app.py", line 1473, in wsgi_app
    response = self.full_dispatch_request()
  File "/Users/Ricardo/.pyenv/versions/3.8.20/lib/python3.8/site-packages/flask/app.py", line 882, in full_dispatch_request
    rv = self.handle_user_exception(e)
  File "/Users/Ricardo/.pyenv/versions/3.8.20/lib/python3.8/site-packages/flask/app.py", line 880, in full_dispatch_request
    rv = self.dispatch_request()
  File "/Users/Ricardo/.pyenv/versions/3.8.20/lib/python3.8/site-packages/flask/app.py", line 865, in dispatch_request
    return self.ensure_sync(self.view_functions[rule.endpoint])(**view_args)  # type: ignore[no-any-return]
  File "/Users/Ricardo/Documents/Software Development/Fy-yur/app.py", line 295, in show_artist
    data = list(filter(lambda d: d['id'] == artist_id, data))[0]
IndexError: list index out of range
2025-02-24 10:02:54,328 ERROR: Exception on /artists/4 [GET] [in /Users/Ricardo/.pyenv/versions/3.8.20/lib/python3.8/site-packages/flask/app.py:838]
Traceback (most recent call last):
  File "/Users/Ricardo/.pyenv/versions/3.8.20/lib/python3.8/site-packages/flask/app.py", line 1473, in wsgi_app
    response = self.full_dispatch_request()
  File "/Users/Ricardo/.pyenv/versions/3.8.20/lib/python3.8/site-packages/flask/app.py", line 882, in full_dispatch_request
    rv = self.handle_user_exception(e)
  File "/Users/Ricardo/.pyenv/versions/3.8.20/lib/python3.8/site-packages/flask/app.py", line 880, in full_dispatch_request
    rv = self.dispatch_request()
  File "/Users/Ricardo/.pyenv/versions/3.8.20/lib/python3.8/site-packages/flask/app.py", line 865, in dispatch_request
    return self.ensure_sync(self.view_functions[rule.endpoint])(**view_args)  # type: ignore[no-any-return]
  File "/Users/Ricardo/Documents/Software Development/Fy-yur/app.py", line 295, in show_artist
    data = list(filter(lambda d: d['id'] == artist_id, data))[0]
IndexError: list index out of range
2025-02-24 10:04:24,607 ERROR: Exception on /artists/4 [GET] [in /Users/Ricardo/.pyenv/versions/3.8.20/lib/python3.8/site-packages/flask/app.py:838]
Traceback (most recent call last):
  File "/Users/Ricardo/.pyenv/versions/3.8.20/lib/python3.8/site-packages/flask/app.py", line 1473, in wsgi_app
    response = self.full_dispatch_request()
  File "/Users/Ricardo/.pyenv/versions/3.8.20/lib/python3.8/site-packages/flask/app.py", line 882, in full_dispatch_request
    rv = self.handle_user_exception(e)
  File "/Users/Ricardo/.pyenv/versions/3.8.20/lib/python3.8/site-packages/flask/app.py", line 880, in full_dispatch_request
    rv = self.dispatch_request()
  File "/Users/Ricardo/.pyenv/versions/3.8.20/lib/python3.8/site-packages/flask/app.py", line 865, in dispatch_request
    return self.ensure_sync(self.view_functions[rule.endpoint])(**view_args)  # type: ignore[no-any-return]
  File "/Users/Ricardo/Documents/Software Development/Fy-yur/app.py", line 295, in show_artist
    data = list(filter(lambda d: d['id'] == artist_id, data))[0]
IndexError: list index out of range
2025-02-24 10:10:27,095 ERROR: Exception on /artists/4 [GET] [in /Users/Ricardo/.pyenv/versions/3.8.20/lib/python3.8/site-packages/flask/app.py:838]
Traceback (most recent call last):
  File "/Users/Ricardo/.pyenv/versions/3.8.20/lib/python3.8/site-packages/flask/app.py", line 1473, in wsgi_app
    response = self.full_dispatch_request()
  File "/Users/Ricardo/.pyenv/versions/3.8.20/lib/python3.8/site-packages/flask/app.py", line 882, in full_dispatch_request
    rv = self.handle_user_exception(e)
  File "/Users/Ricardo/.pyenv/versions/3.8.20/lib/python3.8/site-packages/flask/app.py", line 880, in full_dispatch_request
    rv = self.dispatch_request()
  File "/Users/Ricardo/.pyenv/versions/3.8.20/lib/python3.8/site-packages/flask/app.py", line 865, in dispatch_request
    return self.ensure_sync(self.view_functions[rule.endpoint])(**view_args)  # type: ignore[no-any-return]
  File "/Users/Ricardo/Documents/Software Development/Fy-yur/app.py", line 295, in show_artist
    data = list(filter(lambda d: d['id'] == artist_id, data))[0]
IndexError: list index out of range
2025-02-24 10:10:27,320 ERROR: Exception on /artists/4 [GET] [in /Users/Ricardo/.pyenv/versions/3.8.20/lib/python3.8/site-packages/flask/app.py:838]
Traceback (most recent call last):
  File "/Users/Ricardo/.pyenv/versions/3.8.20/lib/python3.8/site-packages/flask/app.py", line 1473, in wsgi_app
    response = self.full_dispatch_request()
  File "/Users/Ricardo/.pyenv/versions/3.8.20/lib/python3.8/site-packages/flask/app.py", line 882, in full_dispatch_request
    rv = self.handle_user_exception(e)
  File "/Users/Ricardo/.pyenv/versions/3.8.20/lib/python3.8/site-packages/flask/app.py", line 880, in full_dispatch_request
    rv = self.dispatch_request()
  File "/Users/Ricardo/.pyenv/versions/3.8.20/lib/python3.8/site-packages/flask/app.py", line 865, in dispatch_request
    return self.ensure_sync(self.view_functions[rule.endpoint])(**view_args)  # type: ignore[no-any-return]
  File "/Users/Ricardo/Documents/Software Development/Fy-yur/app.py", line 295, in show_artist
    data = list(filter(lambda d: d['id'] == artist_id, data))[0]
IndexError: list index out of range
2025-02-24 10:13:43,455 INFO: errors [in /Users/Ricardo/Documents/Software Development/Fy-yur/app.py:440]
2025-02-24 11:17:03,647 INFO: errors [in /Users/Ricardo/Documents/Software Development/Fy-yur/app.py:486]
2025-02-24 11:19:56,566 INFO: errors [in /Users/Ricardo/Documents/Software Development/Fy-yur/app.py:486]
2025-02-24 11:24:10,369 INFO: errors [in /Users/Ricardo/Documents/Software Development/Fy-yur/app.py:486]
2025-02-24 11:25:13,108 INFO: errors [in /Users/Ricardo/Documents/Software Development/Fy-yur/app.py:486]
2025-02-24 11:27:13,782 INFO: errors [in /Users/Ricardo/Documents/Software Development/Fy-yur/app.py:486]
2025-02-24 11:27:23,734 INFO: errors [in /Users/Ricardo/Documents/Software Development/Fy-yur/app.py:486]
2025-02-24 11:27:31,514 INFO: errors [in /Users/Ricardo/Documents/Software Development/Fy-yur/app.py:486]
2025-02-24 11:40:31,458 INFO: errors [in /Users/Ricardo/Documents/Software Development/Fy-yur/app.py:516]
2025-02-24 11:41:03,186 INFO: errors [in /Users/Ricardo/Documents/Software Development/Fy-yur/app.py:516]
2025-02-24 11:55:28,699 INFO: errors [in /Users/Ricardo/Documents/Software Development/Fy-yur/app.py:537]
2025-02-24 11:55:30,691 ERROR: Exception on /shows/create [POST] [in /Users/Ricardo/.pyenv/versions/3.8.20/lib/python3.8/site-packages/flask/app.py:838]
Traceback (most recent call last):
  File "/Users/Ricardo/.pyenv/versions/3.8.20/lib/python3.8/site-packages/flask/app.py", line 1473, in wsgi_app
    response = self.full_dispatch_request()
  File "/Users/Ricardo/.pyenv/versions/3.8.20/lib/python3.8/site-packages/flask/app.py", line 882, in full_dispatch_request
    rv = self.handle_user_exception(e)
  File "/Users/Ricardo/.pyenv/versions/3.8.20/lib/python3.8/site-packages/flask/app.py", line 880, in full_dispatch_request
    rv = self.dispatch_request()
  File "/Users/Ricardo/.pyenv/versions/3.8.20/lib/python3.8/site-packages/flask/app.py", line 865, in dispatch_request
    return self.ensure_sync(self.view_functions[rule.endpoint])(**view_args)  # type: ignore[no-any-return]
  File "/Users/Ricardo/Documents/Software Development/Fy-yur/app.py", line 488, in create_show_submission
    @app.route('/shows/create', methods=['POST'])
  File "/Users/Ricardo/.pyenv/versions/3.8.20/lib/python3.8/site-packages/flask/sansio/scaffold.py", line 46, in wrapper_func
    self._check_setup_finished(f_name)
  File "/Users/Ricardo/.pyenv/versions/3.8.20/lib/python3.8/site-packages/flask/sansio/app.py", line 415, in _check_setup_finished
    raise AssertionError(
AssertionError: The setup method 'route' can no longer be called on the application. It has already handled its first request, any changes will not be applied consistently.
Make sure all imports, decorators, functions, etc. needed to set up the application are done before running it.
2025-02-24 11:55:52,109 ERROR: Exception on /shows/create [POST] [in /Users/Ricardo/.pyenv/versions/3.8.20/lib/python3.8/site-packages/flask/app.py:838]
Traceback (most recent call last):
  File "/Users/Ricardo/.pyenv/versions/3.8.20/lib/python3.8/site-packages/flask/app.py", line 1473, in wsgi_app
    response = self.full_dispatch_request()
  File "/Users/Ricardo/.pyenv/versions/3.8.20/lib/python3.8/site-packages/flask/app.py", line 882, in full_dispatch_request
    rv = self.handle_user_exception(e)
  File "/Users/Ricardo/.pyenv/versions/3.8.20/lib/python3.8/site-packages/flask/app.py", line 880, in full_dispatch_request
    rv = self.dispatch_request()
  File "/Users/Ricardo/.pyenv/versions/3.8.20/lib/python3.8/site-packages/flask/app.py", line 865, in dispatch_request
    return self.ensure_sync(self.view_functions[rule.endpoint])(**view_args)  # type: ignore[no-any-return]
  File "/Users/Ricardo/Documents/Software Development/Fy-yur/app.py", line 488, in create_show_submission
    @app.route('/shows/create', methods=['POST'])
  File "/Users/Ricardo/.pyenv/versions/3.8.20/lib/python3.8/site-packages/flask/sansio/scaffold.py", line 46, in wrapper_func
    self._check_setup_finished(f_name)
  File "/Users/Ricardo/.pyenv/versions/3.8.20/lib/python3.8/site-packages/flask/sansio/app.py", line 415, in _check_setup_finished
    raise AssertionError(
AssertionError: The setup method 'route' can no longer be called on the application. It has already handled its first request, any changes will not be applied consistently.
Make sure all imports, decorators, functions, etc. needed to set up the application are done before running it.
2025-02-24 11:56:10,980 INFO: errors [in /Users/Ricardo/Documents/Software Development/Fy-yur/app.py:537]
2025-02-24 11:56:17,595 ERROR: Exception on /shows/create [POST] [in /Users/Ricardo/.pyenv/versions/3.8.20/lib/python3.8/site-packages/flask/app.py:838]
Traceback (most recent call last):
  File "/Users/Ricardo/.pyenv/versions/3.8.20/lib/python3.8/site-packages/flask/app.py", line 1473, in wsgi_app
    response = self.full_dispatch_request()
  File "/Users/Ricardo/.pyenv/versions/3.8.20/lib/python3.8/site-packages/flask/app.py", line 882, in full_dispatch_request
    rv = self.handle_user_exception(e)
  File "/Users/Ricardo/.pyenv/versions/3.8.20/lib/python3.8/site-packages/flask/app.py", line 880, in full_dispatch_request
    rv = self.dispatch_request()
  File "/Users/Ricardo/.pyenv/versions/3.8.20/lib/python3.8/site-packages/flask/app.py", line 865, in dispatch_request
    return self.ensure_sync(self.view_functions[rule.endpoint])(**view_args)  # type: ignore[no-any-return]
  File "/Users/Ricardo/Documents/Software Development/Fy-yur/app.py", line 488, in create_show_submission
    @app.route('/shows/create', methods=['POST'])
  File "/Users/Ricardo/.pyenv/versions/3.8.20/lib/python3.8/site-packages/flask/sansio/scaffold.py", line 46, in wrapper_func
    self._check_setup_finished(f_name)
  File "/Users/Ricardo/.pyenv/versions/3.8.20/lib/python3.8/site-packages/flask/sansio/app.py", line 415, in _check_setup_finished
    raise AssertionError(
AssertionError: The setup method 'route' can no longer be called on the application. It has already handled its first request, any changes will not be applied consistently.
Make sure all imports, decorators, functions, etc. needed to set up the application are done before running it.
2025-02-24 11:58:07,805 INFO: errors [in /Users/Ricardo/Documents/Software Development/Fy-yur/app.py:534]
2025-02-24 11:59:19,500 INFO: errors [in /Users/Ricardo/Documents/Software Development/Fy-yur/app.py:534]
2025-02-24 14:53:29,661 INFO: errors [in /Users/Ricardo/Documents/Software Development/Fy-yur/app.py:598]
2025-02-24 14:55:19,183 INFO: errors [in /Users/Ricardo/Documents/Software Development/Fy-yur/app.py:598]
2025-02-24 14:56:56,502 INFO: errors [in /Users/Ricardo/Documents/Software Development/Fy-yur/app.py:598]
2025-02-24 15:04:11,572 INFO: errors [in /Users/Ricardo/Documents/Software Development/Fy-yur/app.py:601]
2025-02-24 15:04:18,630 ERROR: Exception on /venues/1/edit [GET] [in /Users/Ricardo/.pyenv/versions/3.8.20/lib/python3.8/site-packages/flask/app.py:838]
Traceback (most recent call last):
  File "/Users/Ricardo/.pyenv/versions/3.8.20/lib/python3.8/site-packages/flask/app.py", line 1473, in wsgi_app
    response = self.full_dispatch_request()
  File "/Users/Ricardo/.pyenv/versions/3.8.20/lib/python3.8/site-packages/flask/app.py", line 882, in full_dispatch_request
    rv = self.handle_user_exception(e)
  File "/Users/Ricardo/.pyenv/versions/3.8.20/lib/python3.8/site-packages/flask/app.py", line 880, in full_dispatch_request
    rv = self.dispatch_request()
  File "/Users/Ricardo/.pyenv/versions/3.8.20/lib/python3.8/site-packages/flask/app.py", line 865, in dispatch_request
    return self.ensure_sync(self.view_functions[rule.endpoint])(**view_args)  # type: ignore[no-any-return]
  File "/Users/Ricardo/Documents/Software Development/Fy-yur/app.py", line 441, in edit_venue
    "address" : venue.address,
AttributeError: 'Artist' object has no attribute 'address'
2025-02-24 15:04:55,375 INFO: errors [in /Users/Ricardo/Documents/Software Development/Fy-yur/app.py:601]
2025-02-24 15:16:04,120 INFO: errors [in /Users/Ricardo/Documents/Software Development/Fy-yur/app.py:638]
2025-02-24 21:05:26,652 INFO: errors [in /Users/Ricardo/Documents/Software Development/Fy-yur/app.py:661]
2025-02-24 21:08:46,784 INFO: errors [in /Users/Ricardo/Documents/Software Development/Fy-yur/app.py:673]
2025-02-24 21:09:05,799 INFO: errors [in /Users/Ricardo/Documents/Software Development/Fy-yur/app.py:673]
2025-02-24 21:15:25,364 INFO: errors [in /Users/Ricardo/Documents/Software Development/Fy-yur/app.py:673]
2025-02-24 21:21:24,613 INFO: errors [in /Users/Ricardo/Documents/Software Development/Fy-yur/app.py:673]
2025-02-24 21:23:20,466 INFO: errors [in /Users/Ricardo/Documents/Software Development/Fy-yur/app.py:673]
2025-02-24 22:13:39,932 INFO: errors [in /Users/Ricardo/Documents/Software Development/Fy-yur/app.py:608]
2025-02-24 22:14:50,651 INFO: errors [in /Users/Ricardo/Documents/Software Development/Fy-yur/app.py:608]
2025-02-24 22:15:11,348 INFO: errors [in /Users/Ricardo/Documents/Software Development/Fy-yur/app.py:608]
2025-02-24 22:15:20,911 INFO: errors [in /Users/Ricardo/Documents/Software Development/Fy-yur/app.py:608]
2025-02-26 07:46:11,255 INFO: errors [in /Users/Ricardo/Documents/Software Development/Fy-yur/app.py:621]
2025-02-26 07:46:22,303 INFO: errors [in /Users/Ricardo/Documents/Software Development/Fy-yur/app.py:621]
2025-02-26 07:49:03,314 INFO: errors [in /Users/Ricardo/Documents/Software Development/Fy-yur/app.py:621]
2025-02-26 07:49:53,823 INFO: errors [in /Users/Ricardo/Documents/Software Development/Fy-yur/app.py:621]
2025-02-26 07:50:05,027 INFO: errors [in /Users/Ricardo/Documents/Software Development/Fy-yur/app.py:621]
2025-02-26 07:51:11,986 INFO: errors [in /Users/Ricardo/Documents/Software Development/Fy-yur/app.py:621]
2025-02-26 08:07:08,098 INFO: errors [in /Users/Ricardo/Documents/Software Development/Fy-yur/app.py:621]
2025-02-26 08:07:20,863 INFO: errors [in /Users/Ricardo/Documents/Software Development/Fy-yur/app.py:621]
2025-02-26 08:08:22,836 INFO: errors [in /Users/Ricardo/Documents/Software Development/Fy-yur/app.py:621]
2025-02-26 08:35:34,000 INFO: errors [in /Users/Ricardo/Documents/Software Development/Fy-yur/app.py:621]
2025-02-26 08:39:02,419 INFO: errors [in /Users/Ricardo/Documents/Software Development/Fy-yur/app.py:621]
2025-02-26 09:33:25,432 INFO: errors [in /Users/Ricardo/Documents/Software Development/Fy-yur/app.py:621]
2025-02-26 09:55:41,267 INFO: errors [in /Users/Ricardo/Documents/Software Development/Fy-yur/app.py:621]
2025-02-26 09:57:31,762 INFO: errors [in /Users/Ricardo/Documents/Software Development/Fy-yur/app.py:624]
2025-02-26 09:57:42,182 ERROR: Exception on /artists/1 [GET] [in /Users/Ricardo/.pyenv/versions/3.8.20/lib/python3.8/site-packages/flask/app.py:838]
Traceback (most recent call last):
  File "/Users/Ricardo/.pyenv/versions/3.8.20/lib/python3.8/site-packages/flask/app.py", line 1473, in wsgi_app
    response = self.full_dispatch_request()
  File "/Users/Ricardo/.pyenv/versions/3.8.20/lib/python3.8/site-packages/flask/app.py", line 882, in full_dispatch_request
    rv = self.handle_user_exception(e)
  File "/Users/Ricardo/.pyenv/versions/3.8.20/lib/python3.8/site-packages/flask/app.py", line 880, in full_dispatch_request
    rv = self.dispatch_request()
  File "/Users/Ricardo/.pyenv/versions/3.8.20/lib/python3.8/site-packages/flask/app.py", line 865, in dispatch_request
    return self.ensure_sync(self.view_functions[rule.endpoint])(**view_args)  # type: ignore[no-any-return]
  File "/Users/Ricardo/Documents/Software Development/Fy-yur/app.py", line 300, in show_artist
    artists_in_db = Artist.query.order_by('id').all()
  File "/Users/Ricardo/.pyenv/versions/3.8.20/lib/python3.8/site-packages/flask_sqlalchemy/model.py", line 22, in __get__
    return cls.query_class(
  File "/Users/Ricardo/.pyenv/versions/3.8.20/lib/python3.8/site-packages/sqlalchemy/orm/query.py", line 275, in __init__
    self._set_entities(entities)
  File "/Users/Ricardo/.pyenv/versions/3.8.20/lib/python3.8/site-packages/sqlalchemy/orm/query.py", line 287, in _set_entities
    self._raw_columns = [
  File "/Users/Ricardo/.pyenv/versions/3.8.20/lib/python3.8/site-packages/sqlalchemy/orm/query.py", line 288, in <listcomp>
    coercions.expect(
  File "/Users/Ricardo/.pyenv/versions/3.8.20/lib/python3.8/site-packages/sqlalchemy/sql/coercions.py", line 388, in expect
    insp._post_inspect
  File "/Users/Ricardo/.pyenv/versions/3.8.20/lib/python3.8/site-packages/sqlalchemy/util/langhelpers.py", line 1257, in __get__
    obj.__dict__[self.__name__] = result = self.fget(obj)
  File "/Users/Ricardo/.pyenv/versions/3.8.20/lib/python3.8/site-packages/sqlalchemy/orm/mapper.py", line 2724, in _post_inspect
    self._check_configure()
  File "/Users/Ricardo/.pyenv/versions/3.8.20/lib/python3.8/site-packages/sqlalchemy/orm/mapper.py", line 2401, in _check_configure
    _configure_registries({self.registry}, cascade=True)
  File "/Users/Ricardo/.pyenv/versions/3.8.20/lib/python3.8/site-packages/sqlalchemy/orm/mapper.py", line 4213, in _configure_registries
    _do_configure_registries(registries, cascade)
  File "/Users/Ricardo/.pyenv/versions/3.8.20/lib/python3.8/site-packages/sqlalchemy/orm/mapper.py", line 4254, in _do_configure_registries
    mapper._post_configure_properties()
  File "/Users/Ricardo/.pyenv/versions/3.8.20/lib/python3.8/site-packages/sqlalchemy/orm/mapper.py", line 2418, in _post_configure_properties
    prop.init()
  File "/Users/Ricardo/.pyenv/versions/3.8.20/lib/python3.8/site-packages/sqlalchemy/orm/interfaces.py", line 589, in init
    self.do_init()
  File "/Users/Ricardo/.pyenv/versions/3.8.20/lib/python3.8/site-packages/sqlalchemy/orm/relationships.py", line 1656, in do_init
    self._setup_entity()
  File "/Users/Ricardo/.pyenv/versions/3.8.20/lib/python3.8/site-packages/sqlalchemy/orm/relationships.py", line 1888, in _setup_entity
    raise sa_exc.ArgumentError(
sqlalchemy.exc.ArgumentError: relationship 'shows' expects a class or a mapper argument (received: <class 'flask_sqlalchemy.extension.SQLAlchemy._make_table_class.<locals>.Table'>)
2025-02-26 10:04:49,714 INFO: errors [in /Users/Ricardo/Documents/Software Development/Fy-yur/app.py:624]
2025-02-26 11:08:49,323 INFO: errors [in /Users/Ricardo/Documents/Software Development/Fy-yur/app.py:624]
2025-02-26 11:08:55,786 ERROR: Exception on /venues [GET] [in /Users/Ricardo/.pyenv/versions/3.8.20/lib/python3.8/site-packages/flask/app.py:838]
Traceback (most recent call last):
  File "/Users/Ricardo/.pyenv/versions/3.8.20/lib/python3.8/site-packages/flask/app.py", line 1473, in wsgi_app
    response = self.full_dispatch_request()
  File "/Users/Ricardo/.pyenv/versions/3.8.20/lib/python3.8/site-packages/flask/app.py", line 882, in full_dispatch_request
    rv = self.handle_user_exception(e)
  File "/Users/Ricardo/.pyenv/versions/3.8.20/lib/python3.8/site-packages/flask/app.py", line 880, in full_dispatch_request
    rv = self.dispatch_request()
  File "/Users/Ricardo/.pyenv/versions/3.8.20/lib/python3.8/site-packages/flask/app.py", line 865, in dispatch_request
    return self.ensure_sync(self.view_functions[rule.endpoint])(**view_args)  # type: ignore[no-any-return]
  File "/Users/Ricardo/Documents/Software Development/Fy-yur/app.py", line 34, in venues
    venues_in_db = Venue.query.order_by('id').all()
  File "/Users/Ricardo/.pyenv/versions/3.8.20/lib/python3.8/site-packages/flask_sqlalchemy/model.py", line 22, in __get__
    return cls.query_class(
  File "/Users/Ricardo/.pyenv/versions/3.8.20/lib/python3.8/site-packages/sqlalchemy/orm/query.py", line 275, in __init__
    self._set_entities(entities)
  File "/Users/Ricardo/.pyenv/versions/3.8.20/lib/python3.8/site-packages/sqlalchemy/orm/query.py", line 287, in _set_entities
    self._raw_columns = [
  File "/Users/Ricardo/.pyenv/versions/3.8.20/lib/python3.8/site-packages/sqlalchemy/orm/query.py", line 288, in <listcomp>
    coercions.expect(
  File "/Users/Ricardo/.pyenv/versions/3.8.20/lib/python3.8/site-packages/sqlalchemy/sql/coercions.py", line 388, in expect
    insp._post_inspect
  File "/Users/Ricardo/.pyenv/versions/3.8.20/lib/python3.8/site-packages/sqlalchemy/util/langhelpers.py", line 1257, in __get__
    obj.__dict__[self.__name__] = result = self.fget(obj)
  File "/Users/Ricardo/.pyenv/versions/3.8.20/lib/python3.8/site-packages/sqlalchemy/orm/mapper.py", line 2724, in _post_inspect
    self._check_configure()
  File "/Users/Ricardo/.pyenv/versions/3.8.20/lib/python3.8/site-packages/sqlalchemy/orm/mapper.py", line 2401, in _check_configure
    _configure_registries({self.registry}, cascade=True)
  File "/Users/Ricardo/.pyenv/versions/3.8.20/lib/python3.8/site-packages/sqlalchemy/orm/mapper.py", line 4213, in _configure_registries
    _do_configure_registries(registries, cascade)
  File "/Users/Ricardo/.pyenv/versions/3.8.20/lib/python3.8/site-packages/sqlalchemy/orm/mapper.py", line 4254, in _do_configure_registries
    mapper._post_configure_properties()
  File "/Users/Ricardo/.pyenv/versions/3.8.20/lib/python3.8/site-packages/sqlalchemy/orm/mapper.py", line 2418, in _post_configure_properties
    prop.init()
  File "/Users/Ricardo/.pyenv/versions/3.8.20/lib/python3.8/site-packages/sqlalchemy/orm/interfaces.py", line 589, in init
    self.do_init()
  File "/Users/Ricardo/.pyenv/versions/3.8.20/lib/python3.8/site-packages/sqlalchemy/orm/relationships.py", line 1661, in do_init
    self._generate_backref()
  File "/Users/Ricardo/.pyenv/versions/3.8.20/lib/python3.8/site-packages/sqlalchemy/orm/relationships.py", line 2147, in _generate_backref
    self._add_reverse_property(self.back_populates)
  File "/Users/Ricardo/.pyenv/versions/3.8.20/lib/python3.8/site-packages/sqlalchemy/orm/relationships.py", line 1616, in _add_reverse_property
    raise sa_exc.ArgumentError(
sqlalchemy.exc.ArgumentError: reverse_property 'artist' on relationship Venue.shows references relationship Show.artist, which does not reference mapper Mapper[Venue(Venue)]
2025-02-26 11:10:13,589 INFO: errors [in /Users/Ricardo/Documents/Software Development/Fy-yur/app.py:624]
2025-02-26 11:12:58,864 INFO: errors [in /Users/Ricardo/Documents/Software Development/Fy-yur/app.py:624]
2025-02-26 11:14:20,717 INFO: errors [in /Users/Ricardo/Documents/Software Development/Fy-yur/app.py:624]
2025-02-26 11:15:52,273 INFO: errors [in /Users/Ricardo/Documents/Software Development/Fy-yur/app.py:624]
2025-02-26 11:16:53,108 INFO: errors [in /Users/Ricardo/Documents/Software Development/Fy-yur/app.py:624]
2025-02-26 11:18:38,972 INFO: errors [in /Users/Ricardo/Documents/Software Development/Fy-yur/app.py:624]
2025-02-26 11:19:43,840 INFO: errors [in /Users/Ricardo/Documents/Software Development/Fy-yur/app.py:624]
2025-02-26 11:21:20,969 INFO: errors [in /Users/Ricardo/Documents/Software Development/Fy-yur/app.py:624]
2025-02-26 11:22:48,103 INFO: errors [in /Users/Ricardo/Documents/Software Development/Fy-yur/app.py:624]
2025-02-26 11:24:40,701 INFO: errors [in /Users/Ricardo/Documents/Software Development/Fy-yur/app.py:624]
2025-02-26 11:24:48,507 INFO: errors [in /Users/Ricardo/Documents/Software Development/Fy-yur/app.py:624]
2025-02-26 11:25:07,911 INFO: errors [in /Users/Ricardo/Documents/Software Development/Fy-yur/app.py:624]
2025-02-26 11:25:32,420 INFO: errors [in /Users/Ricardo/Documents/Software Development/Fy-yur/app.py:624]
2025-02-26 11:35:17,121 INFO: errors [in /Users/Ricardo/Documents/Software Development/Fy-yur/app.py:624]
2025-02-26 11:48:04,711 INFO: errors [in /Users/Ricardo/Documents/Software Development/Fy-yur/app.py:624]
2025-02-26 11:50:34,917 INFO: errors [in /Users/Ricardo/Documents/Software Development/Fy-yur/app.py:619]
2025-02-26 11:50:49,298 ERROR: Exception on /artists/1 [GET] [in /Users/Ricardo/.pyenv/versions/3.8.20/lib/python3.8/site-packages/flask/app.py:838]
Traceback (most recent call last):
  File "/Users/Ricardo/.pyenv/versions/3.8.20/lib/python3.8/site-packages/flask/app.py", line 1473, in wsgi_app
    response = self.full_dispatch_request()
  File "/Users/Ricardo/.pyenv/versions/3.8.20/lib/python3.8/site-packages/flask/app.py", line 882, in full_dispatch_request
    rv = self.handle_user_exception(e)
  File "/Users/Ricardo/.pyenv/versions/3.8.20/lib/python3.8/site-packages/flask/app.py", line 880, in full_dispatch_request
    rv = self.dispatch_request()
  File "/Users/Ricardo/.pyenv/versions/3.8.20/lib/python3.8/site-packages/flask/app.py", line 865, in dispatch_request
    return self.ensure_sync(self.view_functions[rule.endpoint])(**view_args)  # type: ignore[no-any-return]
  File "/Users/Ricardo/Documents/Software Development/Fy-yur/app.py", line 312, in show_artist
    "venue_name": show.name,
AttributeError: 'Show' object has no attribute 'name'
2025-02-26 11:54:04,957 INFO: errors [in /Users/Ricardo/Documents/Software Development/Fy-yur/app.py:621]
2025-02-26 13:07:31,648 INFO: errors [in /Users/Ricardo/Documents/Software Development/Fy-yur/app.py:619]
2025-02-26 13:10:38,691 ERROR: Exception on /shows [GET] [in /Users/Ricardo/.pyenv/versions/3.8.20/lib/python3.8/site-packages/flask/app.py:838]
Traceback (most recent call last):
  File "/Users/Ricardo/.pyenv/versions/3.8.20/lib/python3.8/site-packages/flask/app.py", line 1473, in wsgi_app
    response = self.full_dispatch_request()
  File "/Users/Ricardo/.pyenv/versions/3.8.20/lib/python3.8/site-packages/flask/app.py", line 882, in full_dispatch_request
    rv = self.handle_user_exception(e)
  File "/Users/Ricardo/.pyenv/versions/3.8.20/lib/python3.8/site-packages/flask/app.py", line 880, in full_dispatch_request
    rv = self.dispatch_request()
  File "/Users/Ricardo/.pyenv/versions/3.8.20/lib/python3.8/site-packages/flask/app.py", line 865, in dispatch_request
    return self.ensure_sync(self.view_functions[rule.endpoint])(**view_args)  # type: ignore[no-any-return]
  File "/Users/Ricardo/Documents/Software Development/Fy-yur/app.py", line 537, in shows
    shows_in_db = db.session.execute(select(show)).fetchall()
NameError: name 'show' is not defined
2025-02-26 13:15:15,953 INFO: errors [in /Users/Ricardo/Documents/Software Development/Fy-yur/app.py:622]
2025-02-26 13:24:17,917 INFO: errors [in /Users/Ricardo/Documents/Software Development/Fy-yur/app.py:622]
2025-02-26 13:26:35,197 ERROR: Exception on /artists/search [POST] [in /Users/Ricardo/.pyenv/versions/3.8.20/lib/python3.8/site-packages/flask/app.py:838]
Traceback (most recent call last):
  File "/Users/Ricardo/.pyenv/versions/3.8.20/lib/python3.8/site-packages/flask/app.py", line 1473, in wsgi_app
    response = self.full_dispatch_request()
  File "/Users/Ricardo/.pyenv/versions/3.8.20/lib/python3.8/site-packages/flask/app.py", line 882, in full_dispatch_request
    rv = self.handle_user_exception(e)
  File "/Users/Ricardo/.pyenv/versions/3.8.20/lib/python3.8/site-packages/flask/app.py", line 880, in full_dispatch_request
    rv = self.dispatch_request()
  File "/Users/Ricardo/.pyenv/versions/3.8.20/lib/python3.8/site-packages/flask/app.py", line 865, in dispatch_request
    return self.ensure_sync(self.view_functions[rule.endpoint])(**view_args)  # type: ignore[no-any-return]
  File "/Users/Ricardo/Documents/Software Development/Fy-yur/app.py", line 279, in search_artists
    num_upcoming_shows = db.session.query(show).filter(
NameError: name 'show' is not defined
2025-02-26 13:27:26,765 INFO: errors [in /Users/Ricardo/Documents/Software Development/Fy-yur/app.py:622]
2025-02-26 13:29:10,650 INFO: errors [in /Users/Ricardo/Documents/Software Development/Fy-yur/app.py:622]
2025-02-26 20:08:27,095 INFO: errors [in /Users/Ricardo/Documents/Software Development/Fy-yur/app.py:634]
2025-02-26 20:08:34,601 ERROR: Exception on /venues/1 [GET] [in /Users/Ricardo/.pyenv/versions/3.8.20/lib/python3.8/site-packages/flask/app.py:838]
Traceback (most recent call last):
  File "/Users/Ricardo/.pyenv/versions/3.8.20/lib/python3.8/site-packages/sqlalchemy/engine/result.py", line 199, in _key_not_found
    self._key_fallback(key, None)
  File "/Users/Ricardo/.pyenv/versions/3.8.20/lib/python3.8/site-packages/sqlalchemy/engine/result.py", line 138, in _key_fallback
    raise KeyError(key) from err
KeyError: 'artist'

The above exception was the direct cause of the following exception:

Traceback (most recent call last):
  File "/Users/Ricardo/.pyenv/versions/3.8.20/lib/python3.8/site-packages/flask/app.py", line 1473, in wsgi_app
    response = self.full_dispatch_request()
  File "/Users/Ricardo/.pyenv/versions/3.8.20/lib/python3.8/site-packages/flask/app.py", line 882, in full_dispatch_request
    rv = self.handle_user_exception(e)
  File "/Users/Ricardo/.pyenv/versions/3.8.20/lib/python3.8/site-packages/flask/app.py", line 880, in full_dispatch_request
    rv = self.dispatch_request()
  File "/Users/Ricardo/.pyenv/versions/3.8.20/lib/python3.8/site-packages/flask/app.py", line 865, in dispatch_request
    return self.ensure_sync(self.view_functions[rule.endpoint])(**view_args)  # type: ignore[no-any-return]
  File "/Users/Ricardo/Documents/Software Development/Fy-yur/app.py", line 126, in show_venue
    "artist_id": show.artist.id,
  File "lib/sqlalchemy/cyextension/resultproxy.pyx", line 66, in sqlalchemy.cyextension.resultproxy.BaseRow.__getattr__
  File "lib/sqlalchemy/cyextension/resultproxy.pyx", line 63, in sqlalchemy.cyextension.resultproxy.BaseRow._get_by_key_impl
  File "/Users/Ricardo/.pyenv/versions/3.8.20/lib/python3.8/site-packages/sqlalchemy/engine/result.py", line 201, in _key_not_found
    raise AttributeError(ke.args[0]) from ke
AttributeError: artist
2025-02-26 20:19:54,230 INFO: errors [in /Users/Ricardo/Documents/Software Development/Fy-yur/app.py:593]
2025-02-26 20:23:36,572 INFO: errors [in /Users/Ricardo/Documents/Software Development/Fy-yur/app.py:596]
2025-02-27 07:08:22,145 INFO: errors [in /Users/Ricardo/Documents/Software Development/Fy-yur/app.py:579]
2025-02-27 07:13:58,468 INFO: errors [in /Users/Ricardo/Documents/Software Development/Fy-yur/app.py:582]
2025-02-27 07:16:59,339 INFO: errors [in /Users/Ricardo/Documents/Software Development/Fy-yur/app.py:582]
2025-02-27 07:20:11,846 INFO: errors [in /Users/Ricardo/Documents/Software Development/Fy-yur/app.py:585]
2025-02-27 07:22:11,965 INFO: errors [in /Users/Ricardo/Documents/Software Development/Fy-yur/app.py:584]
2025-02-27 07:26:24,844 INFO: errors [in /Users/Ricardo/Documents/Software Development/Fy-yur/app.py:585]
2025-02-27 07:26:33,782 ERROR: Exception on /artists/create [POST] [in /Users/Ricardo/.pyenv/versions/3.8.20/lib/python3.8/site-packages/flask/app.py:838]
Traceback (most recent call last):
  File "/Users/Ricardo/.pyenv/versions/3.8.20/lib/python3.8/site-packages/flask/app.py", line 1473, in wsgi_app
    response = self.full_dispatch_request()
  File "/Users/Ricardo/.pyenv/versions/3.8.20/lib/python3.8/site-packages/flask/app.py", line 883, in full_dispatch_request
    return self.finalize_request(rv)
  File "/Users/Ricardo/.pyenv/versions/3.8.20/lib/python3.8/site-packages/flask/app.py", line 902, in finalize_request
    response = self.make_response(rv)
  File "/Users/Ricardo/.pyenv/versions/3.8.20/lib/python3.8/site-packages/flask/app.py", line 1174, in make_response
    raise TypeError(
TypeError: The view function for 'create_artist_submission' did not return a valid response. The function either returned None or ended without a return statement.
2025-02-27 07:27:08,268 INFO: errors [in /Users/Ricardo/Documents/Software Development/Fy-yur/app.py:585]
2025-02-27 07:27:28,001 ERROR: Exception on /artists/create [POST] [in /Users/Ricardo/.pyenv/versions/3.8.20/lib/python3.8/site-packages/flask/app.py:838]
Traceback (most recent call last):
  File "/Users/Ricardo/.pyenv/versions/3.8.20/lib/python3.8/site-packages/flask/app.py", line 1473, in wsgi_app
    response = self.full_dispatch_request()
  File "/Users/Ricardo/.pyenv/versions/3.8.20/lib/python3.8/site-packages/flask/app.py", line 883, in full_dispatch_request
    return self.finalize_request(rv)
  File "/Users/Ricardo/.pyenv/versions/3.8.20/lib/python3.8/site-packages/flask/app.py", line 902, in finalize_request
    response = self.make_response(rv)
  File "/Users/Ricardo/.pyenv/versions/3.8.20/lib/python3.8/site-packages/flask/app.py", line 1203, in make_response
    raise TypeError(
  File "/Users/Ricardo/.pyenv/versions/3.8.20/lib/python3.8/site-packages/flask/app.py", line 1198, in make_response
    rv = self.response_class.force_type(
  File "/Users/Ricardo/.pyenv/versions/3.8.20/lib/python3.8/site-packages/werkzeug/wrappers/response.py", line 237, in force_type
    response = Response(*run_wsgi_app(response, environ))
  File "/Users/Ricardo/.pyenv/versions/3.8.20/lib/python3.8/site-packages/werkzeug/test.py", line 1264, in run_wsgi_app
    app_rv = app(environ, start_response)
TypeError: create_artist_form() takes 0 positional arguments but 2 were given
The view function did not return a valid response. The return type must be a string, dict, list, tuple with headers or status, Response instance, or WSGI callable, but it was a function.
2025-02-27 07:27:48,739 INFO: errors [in /Users/Ricardo/Documents/Software Development/Fy-yur/app.py:585]
2025-02-27 07:45:03,308 INFO: errors [in /Users/Ricardo/Documents/Software Development/Fy-yur/app.py:610]
2025-02-27 07:49:55,993 INFO: errors [in /Users/Ricardo/Documents/Software Development/Fy-yur/app.py:610]
2025-02-27 07:53:31,135 INFO: errors [in /Users/Ricardo/Documents/Software Development/Fy-yur/app.py:610]
2025-02-27 07:58:12,911 ERROR: Exception on /artists/5/edit [POST] [in /Users/Ricardo/.pyenv/versions/3.8.20/lib/python3.8/site-packages/flask/app.py:838]
Traceback (most recent call last):
  File "/Users/Ricardo/.pyenv/versions/3.8.20/lib/python3.8/site-packages/flask/app.py", line 1473, in wsgi_app
    response = self.full_dispatch_request()
  File "/Users/Ricardo/.pyenv/versions/3.8.20/lib/python3.8/site-packages/flask/app.py", line 882, in full_dispatch_request
    rv = self.handle_user_exception(e)
  File "/Users/Ricardo/.pyenv/versions/3.8.20/lib/python3.8/site-packages/flask/app.py", line 880, in full_dispatch_request
    rv = self.dispatch_request()
  File "/Users/Ricardo/.pyenv/versions/3.8.20/lib/python3.8/site-packages/flask/app.py", line 865, in dispatch_request
    return self.ensure_sync(self.view_functions[rule.endpoint])(**view_args)  # type: ignore[no-any-return]
  File "/Users/Ricardo/Documents/Software Development/Fy-yur/app.py", line 397, in edit_artist_submission
    return redirect(url_for('edit_artist_submission'))
  File "/Users/Ricardo/.pyenv/versions/3.8.20/lib/python3.8/site-packages/flask/helpers.py", line 220, in url_for
    return current_app.url_for(
  File "/Users/Ricardo/.pyenv/versions/3.8.20/lib/python3.8/site-packages/flask/app.py", line 1084, in url_for
    return self.handle_url_build_error(error, endpoint, values)
  File "/Users/Ricardo/.pyenv/versions/3.8.20/lib/python3.8/site-packages/flask/app.py", line 1073, in url_for
    rv = url_adapter.build(  # type: ignore[union-attr]
  File "/Users/Ricardo/.pyenv/versions/3.8.20/lib/python3.8/site-packages/werkzeug/routing/map.py", line 924, in build
    raise BuildError(endpoint, values, method, self)
werkzeug.routing.exceptions.BuildError: Could not build url for endpoint 'edit_artist_submission'. Did you forget to specify values ['artist_id']?
2025-02-27 09:23:29,566 INFO: errors [in /Users/Ricardo/Documents/Software Development/Fy-yur/app.py:610]
2025-02-27 09:31:44,735 INFO: errors [in /Users/Ricardo/Documents/Software Development/Fy-yur/app.py:610]
2025-02-27 10:01:01,195 INFO: errors [in /Users/Ricardo/Documents/Software Development/Fy-yur/app.py:610]
2025-02-27 10:11:24,658 INFO: errors [in /Users/Ricardo/Documents/Software Development/Fy-yur/app.py:610]
2025-02-27 11:32:46,394 INFO: errors [in /Users/Ricardo/Documents/Software Development/Fy-yur/app.py:609]
2025-02-27 11:54:48,957 INFO: errors [in /Users/Ricardo/Documents/Software Development/Fy-yur/app.py:611]
2025-02-27 11:55:03,775 ERROR: Exception on /artists/5 [GET] [in /Users/Ricardo/.pyenv/versions/3.8.20/lib/python3.8/site-packages/flask/app.py:838]
Traceback (most recent call last):
  File "/Users/Ricardo/.pyenv/versions/3.8.20/lib/python3.8/site-packages/flask/app.py", line 1473, in wsgi_app
    response = self.full_dispatch_request()
  File "/Users/Ricardo/.pyenv/versions/3.8.20/lib/python3.8/site-packages/flask/app.py", line 882, in full_dispatch_request
    rv = self.handle_user_exception(e)
  File "/Users/Ricardo/.pyenv/versions/3.8.20/lib/python3.8/site-packages/flask/app.py", line 880, in full_dispatch_request
    rv = self.dispatch_request()
  File "/Users/Ricardo/.pyenv/versions/3.8.20/lib/python3.8/site-packages/flask/app.py", line 865, in dispatch_request
    return self.ensure_sync(self.view_functions[rule.endpoint])(**view_args)  # type: ignore[no-any-return]
  File "/Users/Ricardo/Documents/Software Development/Fy-yur/app.py", line 338, in show_artist
    return render_template('pages/show_artist.html', artist=artist_data)
  File "/Users/Ricardo/.pyenv/versions/3.8.20/lib/python3.8/site-packages/flask/templating.py", line 150, in render_template
    return _render(app, template, context)
  File "/Users/Ricardo/.pyenv/versions/3.8.20/lib/python3.8/site-packages/flask/templating.py", line 131, in _render
    rv = template.render(context)
  File "/Users/Ricardo/.pyenv/versions/3.8.20/lib/python3.8/site-packages/jinja2/environment.py", line 1295, in render
    self.environment.handle_exception()
  File "/Users/Ricardo/.pyenv/versions/3.8.20/lib/python3.8/site-packages/jinja2/environment.py", line 942, in handle_exception
    raise rewrite_traceback_stack(source=source)
  File "/Users/Ricardo/Documents/Software Development/Fy-yur/templates/pages/show_artist.html", line 1, in top-level template code
    {% extends 'layouts/main.html' %}
  File "/Users/Ricardo/Documents/Software Development/Fy-yur/templates/layouts/main.html", line 103, in top-level template code
    {% block content %}{% endblock %}
  File "/Users/Ricardo/Documents/Software Development/Fy-yur/templates/pages/show_artist.html", line 54, in block 'content'
    <h6>{{ show.start_time|datetime('full') }}</h6>
  File "/Users/Ricardo/Documents/Software Development/Fy-yur/app.py", line 15, in format_datetime
    date = dateutil.parser.parse(value)
  File "/Users/Ricardo/.pyenv/versions/3.8.20/lib/python3.8/site-packages/dateutil/parser.py", line 1168, in parse
    return DEFAULTPARSER.parse(timestr, **kwargs)
  File "/Users/Ricardo/.pyenv/versions/3.8.20/lib/python3.8/site-packages/dateutil/parser.py", line 556, in parse
    res, skipped_tokens = self._parse(timestr, **kwargs)
  File "/Users/Ricardo/.pyenv/versions/3.8.20/lib/python3.8/site-packages/dateutil/parser.py", line 675, in _parse
    l = _timelex.split(timestr)         # Splits the timestr into tokens
  File "/Users/Ricardo/.pyenv/versions/3.8.20/lib/python3.8/site-packages/dateutil/parser.py", line 192, in split
    return list(cls(s))
  File "/Users/Ricardo/.pyenv/versions/3.8.20/lib/python3.8/site-packages/dateutil/parser.py", line 60, in __init__
    raise TypeError('Parser must be a string or character stream, not '
TypeError: Parser must be a string or character stream, not datetime
2025-02-27 11:59:16,560 ERROR: Exception on /artists/5 [GET] [in /Users/Ricardo/.pyenv/versions/3.8.20/lib/python3.8/site-packages/flask/app.py:838]
Traceback (most recent call last):
  File "/Users/Ricardo/.pyenv/versions/3.8.20/lib/python3.8/site-packages/flask/app.py", line 1473, in wsgi_app
    response = self.full_dispatch_request()
  File "/Users/Ricardo/.pyenv/versions/3.8.20/lib/python3.8/site-packages/flask/app.py", line 882, in full_dispatch_request
    rv = self.handle_user_exception(e)
  File "/Users/Ricardo/.pyenv/versions/3.8.20/lib/python3.8/site-packages/flask/app.py", line 880, in full_dispatch_request
    rv = self.dispatch_request()
  File "/Users/Ricardo/.pyenv/versions/3.8.20/lib/python3.8/site-packages/flask/app.py", line 865, in dispatch_request
    return self.ensure_sync(self.view_functions[rule.endpoint])(**view_args)  # type: ignore[no-any-return]
  File "/Users/Ricardo/Documents/Software Development/Fy-yur/app.py", line 338, in show_artist
    return render_template('pages/show_artist.html', artist=artist_data)
  File "/Users/Ricardo/.pyenv/versions/3.8.20/lib/python3.8/site-packages/flask/templating.py", line 150, in render_template
    return _render(app, template, context)
  File "/Users/Ricardo/.pyenv/versions/3.8.20/lib/python3.8/site-packages/flask/templating.py", line 131, in _render
    rv = template.render(context)
  File "/Users/Ricardo/.pyenv/versions/3.8.20/lib/python3.8/site-packages/jinja2/environment.py", line 1295, in render
    self.environment.handle_exception()
  File "/Users/Ricardo/.pyenv/versions/3.8.20/lib/python3.8/site-packages/jinja2/environment.py", line 942, in handle_exception
    raise rewrite_traceback_stack(source=source)
  File "/Users/Ricardo/Documents/Software Development/Fy-yur/templates/pages/show_artist.html", line 1, in top-level template code
    {% extends 'layouts/main.html' %}
  File "/Users/Ricardo/Documents/Software Development/Fy-yur/templates/layouts/main.html", line 103, in top-level template code
    {% block content %}{% endblock %}
  File "/Users/Ricardo/Documents/Software Development/Fy-yur/templates/pages/show_artist.html", line 54, in block 'content'
    <h6>{{ show.start_time|datetime('full') }}</h6>
  File "/Users/Ricardo/Documents/Software Development/Fy-yur/app.py", line 15, in format_datetime
    date = dateutil.parser.parse(value)
  File "/Users/Ricardo/.pyenv/versions/3.8.20/lib/python3.8/site-packages/dateutil/parser.py", line 1168, in parse
    return DEFAULTPARSER.parse(timestr, **kwargs)
  File "/Users/Ricardo/.pyenv/versions/3.8.20/lib/python3.8/site-packages/dateutil/parser.py", line 556, in parse
    res, skipped_tokens = self._parse(timestr, **kwargs)
  File "/Users/Ricardo/.pyenv/versions/3.8.20/lib/python3.8/site-packages/dateutil/parser.py", line 675, in _parse
    l = _timelex.split(timestr)         # Splits the timestr into tokens
  File "/Users/Ricardo/.pyenv/versions/3.8.20/lib/python3.8/site-packages/dateutil/parser.py", line 192, in split
    return list(cls(s))
  File "/Users/Ricardo/.pyenv/versions/3.8.20/lib/python3.8/site-packages/dateutil/parser.py", line 60, in __init__
    raise TypeError('Parser must be a string or character stream, not '
TypeError: Parser must be a string or character stream, not datetime
2025-02-27 12:01:03,975 ERROR: Exception on /artists/5 [GET] [in /Users/Ricardo/.pyenv/versions/3.8.20/lib/python3.8/site-packages/flask/app.py:838]
Traceback (most recent call last):
  File "/Users/Ricardo/.pyenv/versions/3.8.20/lib/python3.8/site-packages/flask/app.py", line 1473, in wsgi_app
    response = self.full_dispatch_request()
  File "/Users/Ricardo/.pyenv/versions/3.8.20/lib/python3.8/site-packages/flask/app.py", line 882, in full_dispatch_request
    rv = self.handle_user_exception(e)
  File "/Users/Ricardo/.pyenv/versions/3.8.20/lib/python3.8/site-packages/flask/app.py", line 880, in full_dispatch_request
    rv = self.dispatch_request()
  File "/Users/Ricardo/.pyenv/versions/3.8.20/lib/python3.8/site-packages/flask/app.py", line 865, in dispatch_request
    return self.ensure_sync(self.view_functions[rule.endpoint])(**view_args)  # type: ignore[no-any-return]
  File "/Users/Ricardo/Documents/Software Development/Fy-yur/app.py", line 338, in show_artist
    return render_template('pages/show_artist.html', artist=artist_data)
  File "/Users/Ricardo/.pyenv/versions/3.8.20/lib/python3.8/site-packages/flask/templating.py", line 150, in render_template
    return _render(app, template, context)
  File "/Users/Ricardo/.pyenv/versions/3.8.20/lib/python3.8/site-packages/flask/templating.py", line 131, in _render
    rv = template.render(context)
  File "/Users/Ricardo/.pyenv/versions/3.8.20/lib/python3.8/site-packages/jinja2/environment.py", line 1295, in render
    self.environment.handle_exception()
  File "/Users/Ricardo/.pyenv/versions/3.8.20/lib/python3.8/site-packages/jinja2/environment.py", line 942, in handle_exception
    raise rewrite_traceback_stack(source=source)
  File "/Users/Ricardo/Documents/Software Development/Fy-yur/templates/pages/show_artist.html", line 1, in top-level template code
    {% extends 'layouts/main.html' %}
  File "/Users/Ricardo/Documents/Software Development/Fy-yur/templates/layouts/main.html", line 103, in top-level template code
    {% block content %}{% endblock %}
  File "/Users/Ricardo/Documents/Software Development/Fy-yur/templates/pages/show_artist.html", line 54, in block 'content'
    <h6>{{ show.start_time|datetime('full') }}</h6>
  File "/Users/Ricardo/Documents/Software Development/Fy-yur/app.py", line 15, in format_datetime
    date = dateutil.parser.parse(value)
  File "/Users/Ricardo/.pyenv/versions/3.8.20/lib/python3.8/site-packages/dateutil/parser.py", line 1168, in parse
    return DEFAULTPARSER.parse(timestr, **kwargs)
  File "/Users/Ricardo/.pyenv/versions/3.8.20/lib/python3.8/site-packages/dateutil/parser.py", line 556, in parse
    res, skipped_tokens = self._parse(timestr, **kwargs)
  File "/Users/Ricardo/.pyenv/versions/3.8.20/lib/python3.8/site-packages/dateutil/parser.py", line 675, in _parse
    l = _timelex.split(timestr)         # Splits the timestr into tokens
  File "/Users/Ricardo/.pyenv/versions/3.8.20/lib/python3.8/site-packages/dateutil/parser.py", line 192, in split
    return list(cls(s))
  File "/Users/Ricardo/.pyenv/versions/3.8.20/lib/python3.8/site-packages/dateutil/parser.py", line 60, in __init__
    raise TypeError('Parser must be a string or character stream, not '
TypeError: Parser must be a string or character stream, not datetime
2025-02-27 12:02:21,250 INFO: errors [in /Users/Ricardo/Documents/Software Development/Fy-yur/app.py:611]
2025-02-27 12:02:29,569 ERROR: Exception on /artists/5 [GET] [in /Users/Ricardo/.pyenv/versions/3.8.20/lib/python3.8/site-packages/flask/app.py:838]
Traceback (most recent call last):
  File "/Users/Ricardo/.pyenv/versions/3.8.20/lib/python3.8/site-packages/flask/app.py", line 1473, in wsgi_app
    response = self.full_dispatch_request()
  File "/Users/Ricardo/.pyenv/versions/3.8.20/lib/python3.8/site-packages/flask/app.py", line 882, in full_dispatch_request
    rv = self.handle_user_exception(e)
  File "/Users/Ricardo/.pyenv/versions/3.8.20/lib/python3.8/site-packages/flask/app.py", line 880, in full_dispatch_request
    rv = self.dispatch_request()
  File "/Users/Ricardo/.pyenv/versions/3.8.20/lib/python3.8/site-packages/flask/app.py", line 865, in dispatch_request
    return self.ensure_sync(self.view_functions[rule.endpoint])(**view_args)  # type: ignore[no-any-return]
  File "/Users/Ricardo/Documents/Software Development/Fy-yur/app.py", line 338, in show_artist
    return render_template('pages/show_artist.html', artist=artist_data)
  File "/Users/Ricardo/.pyenv/versions/3.8.20/lib/python3.8/site-packages/flask/templating.py", line 150, in render_template
    return _render(app, template, context)
  File "/Users/Ricardo/.pyenv/versions/3.8.20/lib/python3.8/site-packages/flask/templating.py", line 131, in _render
    rv = template.render(context)
  File "/Users/Ricardo/.pyenv/versions/3.8.20/lib/python3.8/site-packages/jinja2/environment.py", line 1295, in render
    self.environment.handle_exception()
  File "/Users/Ricardo/.pyenv/versions/3.8.20/lib/python3.8/site-packages/jinja2/environment.py", line 942, in handle_exception
    raise rewrite_traceback_stack(source=source)
  File "/Users/Ricardo/Documents/Software Development/Fy-yur/templates/pages/show_artist.html", line 1, in top-level template code
    {% extends 'layouts/main.html' %}
  File "/Users/Ricardo/Documents/Software Development/Fy-yur/templates/layouts/main.html", line 103, in top-level template code
    {% block content %}{% endblock %}
  File "/Users/Ricardo/Documents/Software Development/Fy-yur/templates/pages/show_artist.html", line 54, in block 'content'
    <h6>{{ show.start_time|datetime('full') }}</h6>
  File "/Users/Ricardo/Documents/Software Development/Fy-yur/app.py", line 15, in format_datetime
    date = dateutil.parser.parse(value)
  File "/Users/Ricardo/.pyenv/versions/3.8.20/lib/python3.8/site-packages/dateutil/parser.py", line 1168, in parse
    return DEFAULTPARSER.parse(timestr, **kwargs)
  File "/Users/Ricardo/.pyenv/versions/3.8.20/lib/python3.8/site-packages/dateutil/parser.py", line 556, in parse
    res, skipped_tokens = self._parse(timestr, **kwargs)
  File "/Users/Ricardo/.pyenv/versions/3.8.20/lib/python3.8/site-packages/dateutil/parser.py", line 675, in _parse
    l = _timelex.split(timestr)         # Splits the timestr into tokens
  File "/Users/Ricardo/.pyenv/versions/3.8.20/lib/python3.8/site-packages/dateutil/parser.py", line 192, in split
    return list(cls(s))
  File "/Users/Ricardo/.pyenv/versions/3.8.20/lib/python3.8/site-packages/dateutil/parser.py", line 60, in __init__
    raise TypeError('Parser must be a string or character stream, not '
TypeError: Parser must be a string or character stream, not datetime
2025-02-27 12:04:30,298 INFO: errors [in /Users/Ricardo/Documents/Software Development/Fy-yur/app.py:610]
2025-02-27 12:08:45,822 INFO: errors [in /Users/Ricardo/Documents/Software Development/Fy-yur/app.py:611]
2025-02-27 12:08:56,434 ERROR: Exception on /artists/5 [GET] [in /Users/Ricardo/.pyenv/versions/3.8.20/lib/python3.8/site-packages/flask/app.py:838]
Traceback (most recent call last):
  File "/Users/Ricardo/.pyenv/versions/3.8.20/lib/python3.8/site-packages/flask/app.py", line 1473, in wsgi_app
    response = self.full_dispatch_request()
  File "/Users/Ricardo/.pyenv/versions/3.8.20/lib/python3.8/site-packages/flask/app.py", line 882, in full_dispatch_request
    rv = self.handle_user_exception(e)
  File "/Users/Ricardo/.pyenv/versions/3.8.20/lib/python3.8/site-packages/flask/app.py", line 880, in full_dispatch_request
    rv = self.dispatch_request()
  File "/Users/Ricardo/.pyenv/versions/3.8.20/lib/python3.8/site-packages/flask/app.py", line 865, in dispatch_request
    return self.ensure_sync(self.view_functions[rule.endpoint])(**view_args)  # type: ignore[no-any-return]
  File "/Users/Ricardo/Documents/Software Development/Fy-yur/app.py", line 338, in show_artist
    return render_template('pages/show_artist.html', artist=artist_data)
  File "/Users/Ricardo/.pyenv/versions/3.8.20/lib/python3.8/site-packages/flask/templating.py", line 150, in render_template
    return _render(app, template, context)
  File "/Users/Ricardo/.pyenv/versions/3.8.20/lib/python3.8/site-packages/flask/templating.py", line 131, in _render
    rv = template.render(context)
  File "/Users/Ricardo/.pyenv/versions/3.8.20/lib/python3.8/site-packages/jinja2/environment.py", line 1295, in render
    self.environment.handle_exception()
  File "/Users/Ricardo/.pyenv/versions/3.8.20/lib/python3.8/site-packages/jinja2/environment.py", line 942, in handle_exception
    raise rewrite_traceback_stack(source=source)
  File "/Users/Ricardo/Documents/Software Development/Fy-yur/templates/pages/show_artist.html", line 1, in top-level template code
    {% extends 'layouts/main.html' %}
  File "/Users/Ricardo/Documents/Software Development/Fy-yur/templates/layouts/main.html", line 103, in top-level template code
    {% block content %}{% endblock %}
  File "/Users/Ricardo/Documents/Software Development/Fy-yur/templates/pages/show_artist.html", line 54, in block 'content'
    <h6>{{ show.start_time|datetime('full') }}</h6>
  File "/Users/Ricardo/Documents/Software Development/Fy-yur/app.py", line 15, in format_datetime
    date = dateutil.parser.parse(value)
  File "/Users/Ricardo/.pyenv/versions/3.8.20/lib/python3.8/site-packages/dateutil/parser.py", line 1168, in parse
    return DEFAULTPARSER.parse(timestr, **kwargs)
  File "/Users/Ricardo/.pyenv/versions/3.8.20/lib/python3.8/site-packages/dateutil/parser.py", line 556, in parse
    res, skipped_tokens = self._parse(timestr, **kwargs)
  File "/Users/Ricardo/.pyenv/versions/3.8.20/lib/python3.8/site-packages/dateutil/parser.py", line 675, in _parse
    l = _timelex.split(timestr)         # Splits the timestr into tokens
  File "/Users/Ricardo/.pyenv/versions/3.8.20/lib/python3.8/site-packages/dateutil/parser.py", line 192, in split
    return list(cls(s))
  File "/Users/Ricardo/.pyenv/versions/3.8.20/lib/python3.8/site-packages/dateutil/parser.py", line 60, in __init__
    raise TypeError('Parser must be a string or character stream, not '
TypeError: Parser must be a string or character stream, not datetime
2025-02-27 12:10:09,064 ERROR: Exception on /artists/1 [GET] [in /Users/Ricardo/.pyenv/versions/3.8.20/lib/python3.8/site-packages/flask/app.py:838]
Traceback (most recent call last):
  File "/Users/Ricardo/.pyenv/versions/3.8.20/lib/python3.8/site-packages/flask/app.py", line 1473, in wsgi_app
    response = self.full_dispatch_request()
  File "/Users/Ricardo/.pyenv/versions/3.8.20/lib/python3.8/site-packages/flask/app.py", line 882, in full_dispatch_request
    rv = self.handle_user_exception(e)
  File "/Users/Ricardo/.pyenv/versions/3.8.20/lib/python3.8/site-packages/flask/app.py", line 880, in full_dispatch_request
    rv = self.dispatch_request()
  File "/Users/Ricardo/.pyenv/versions/3.8.20/lib/python3.8/site-packages/flask/app.py", line 865, in dispatch_request
    return self.ensure_sync(self.view_functions[rule.endpoint])(**view_args)  # type: ignore[no-any-return]
  File "/Users/Ricardo/Documents/Software Development/Fy-yur/app.py", line 338, in show_artist
    return render_template('pages/show_artist.html', artist=artist_data)
  File "/Users/Ricardo/.pyenv/versions/3.8.20/lib/python3.8/site-packages/flask/templating.py", line 150, in render_template
    return _render(app, template, context)
  File "/Users/Ricardo/.pyenv/versions/3.8.20/lib/python3.8/site-packages/flask/templating.py", line 131, in _render
    rv = template.render(context)
  File "/Users/Ricardo/.pyenv/versions/3.8.20/lib/python3.8/site-packages/jinja2/environment.py", line 1295, in render
    self.environment.handle_exception()
  File "/Users/Ricardo/.pyenv/versions/3.8.20/lib/python3.8/site-packages/jinja2/environment.py", line 942, in handle_exception
    raise rewrite_traceback_stack(source=source)
  File "/Users/Ricardo/Documents/Software Development/Fy-yur/templates/pages/show_artist.html", line 1, in top-level template code
    {% extends 'layouts/main.html' %}
  File "/Users/Ricardo/Documents/Software Development/Fy-yur/templates/layouts/main.html", line 103, in top-level template code
    {% block content %}{% endblock %}
  File "/Users/Ricardo/Documents/Software Development/Fy-yur/templates/pages/show_artist.html", line 54, in block 'content'
    <h6>{{ show.start_time|datetime('full') }}</h6>
  File "/Users/Ricardo/Documents/Software Development/Fy-yur/app.py", line 15, in format_datetime
    date = dateutil.parser.parse(value)
  File "/Users/Ricardo/.pyenv/versions/3.8.20/lib/python3.8/site-packages/dateutil/parser.py", line 1168, in parse
    return DEFAULTPARSER.parse(timestr, **kwargs)
  File "/Users/Ricardo/.pyenv/versions/3.8.20/lib/python3.8/site-packages/dateutil/parser.py", line 556, in parse
    res, skipped_tokens = self._parse(timestr, **kwargs)
  File "/Users/Ricardo/.pyenv/versions/3.8.20/lib/python3.8/site-packages/dateutil/parser.py", line 675, in _parse
    l = _timelex.split(timestr)         # Splits the timestr into tokens
  File "/Users/Ricardo/.pyenv/versions/3.8.20/lib/python3.8/site-packages/dateutil/parser.py", line 192, in split
    return list(cls(s))
  File "/Users/Ricardo/.pyenv/versions/3.8.20/lib/python3.8/site-packages/dateutil/parser.py", line 60, in __init__
    raise TypeError('Parser must be a string or character stream, not '
TypeError: Parser must be a string or character stream, not datetime
