
2025-02-21 11:41:32,953 INFO: errors [in /Users/Ricardo/Documents/Software Development/Fy-yur/app.py:506]
2025-02-21 12:02:24,958 INFO: errors [in /Users/Ricardo/Documents/Software Development/Fy-yur/app.py:517]
2025-02-21 12:58:36,048 INFO: errors [in /Users/Ricardo/Documents/Software Development/Fy-yur/app.py:497]
2025-02-21 12:59:05,132 INFO: errors [in /Users/Ricardo/Documents/Software Development/Fy-yur/app.py:497]
2025-02-21 12:59:18,372 INFO: errors [in /Users/Ricardo/Documents/Software Development/Fy-yur/app.py:497]
2025-02-23 20:50:19,533 INFO: errors [in /Users/Ricardo/Documents/Software Development/Fy-yur/app.py:514]
2025-02-23 20:51:20,919 INFO: errors [in /Users/Ricardo/Documents/Software Development/Fy-yur/app.py:514]
2025-02-24 08:20:14,391 INFO: errors [in /Users/Ricardo/Documents/Software Development/Fy-yur/app.py:500]
2025-02-24 08:20:43,841 INFO: errors [in /Users/Ricardo/Documents/Software Development/Fy-yur/app.py:500]
2025-02-24 08:21:30,245 INFO: errors [in /Users/Ricardo/Documents/Software Development/Fy-yur/app.py:500]
2025-02-24 08:22:06,335 INFO: errors [in /Users/Ricardo/Documents/Software Development/Fy-yur/app.py:500]
2025-02-24 08:53:05,717 INFO: errors [in /Users/Ricardo/Documents/Software Development/Fy-yur/app.py:470]
2025-02-24 08:54:53,250 ERROR: Exception on /venues/1 [GET] [in /Users/Ricardo/.pyenv/versions/3.8.20/lib/python3.8/site-packages/flask/app.py:838]
Traceback (most recent call last):
  File "/Users/Ricardo/.pyenv/versions/3.8.20/lib/python3.8/site-packages/flask/app.py", line 1473, in wsgi_app
    response = self.full_dispatch_request()
  File "/Users/Ricardo/.pyenv/versions/3.8.20/lib/python3.8/site-packages/flask/app.py", line 882, in full_dispatch_request
    rv = self.handle_user_exception(e)
  File "/Users/Ricardo/.pyenv/versions/3.8.20/lib/python3.8/site-packages/flask/app.py", line 880, in full_dispatch_request
    rv = self.dispatch_request()
  File "/Users/Ricardo/.pyenv/versions/3.8.20/lib/python3.8/site-packages/flask/app.py", line 865, in dispatch_request
    return self.ensure_sync(self.view_functions[rule.endpoint])(**view_args)  # type: ignore[no-any-return]
  File "/Users/Ricardo/Documents/Software Development/Fy-yur/app.py", line 148, in show_venue
    show_rel = db.session.query(shows).filter_by(venue_id=venue.id, artist_id=artist.id).first()
  File "/Users/Ricardo/.pyenv/versions/3.8.20/lib/python3.8/site-packages/sqlalchemy/orm/scoping.py", line 1681, in query
    return self._proxied.query(*entities, **kwargs)
  File "/Users/Ricardo/.pyenv/versions/3.8.20/lib/python3.8/site-packages/sqlalchemy/orm/session.py", line 2955, in query
    return self._query_cls(entities, self, **kwargs)
  File "/Users/Ricardo/.pyenv/versions/3.8.20/lib/python3.8/site-packages/sqlalchemy/orm/query.py", line 275, in __init__
    self._set_entities(entities)
  File "/Users/Ricardo/.pyenv/versions/3.8.20/lib/python3.8/site-packages/sqlalchemy/orm/query.py", line 287, in _set_entities
    self._raw_columns = [
  File "/Users/Ricardo/.pyenv/versions/3.8.20/lib/python3.8/site-packages/sqlalchemy/orm/query.py", line 288, in <listcomp>
    coercions.expect(
  File "/Users/Ricardo/.pyenv/versions/3.8.20/lib/python3.8/site-packages/sqlalchemy/sql/coercions.py", line 332, in expect
    return lambdas.LambdaElement(
  File "/Users/Ricardo/.pyenv/versions/3.8.20/lib/python3.8/site-packages/sqlalchemy/sql/lambdas.py", line 213, in __init__
    rec = self._retrieve_tracker_rec(fn, apply_propagate_attrs, opts)
  File "/Users/Ricardo/.pyenv/versions/3.8.20/lib/python3.8/site-packages/sqlalchemy/sql/lambdas.py", line 229, in _retrieve_tracker_rec
    tracker = AnalyzedCode.get(
  File "/Users/Ricardo/.pyenv/versions/3.8.20/lib/python3.8/site-packages/sqlalchemy/sql/lambdas.py", line 753, in get
    cls._fns[fn.__code__] = analyzed = AnalyzedCode(
  File "/Users/Ricardo/.pyenv/versions/3.8.20/lib/python3.8/site-packages/sqlalchemy/sql/lambdas.py", line 795, in __init__
    self._setup_additional_closure_trackers(fn, lambda_element, opts)
  File "/Users/Ricardo/.pyenv/versions/3.8.20/lib/python3.8/site-packages/sqlalchemy/sql/lambdas.py", line 863, in _setup_additional_closure_trackers
    analyzed_function = AnalyzedFunction(
  File "/Users/Ricardo/.pyenv/versions/3.8.20/lib/python3.8/site-packages/sqlalchemy/sql/lambdas.py", line 1129, in __init__
    self._instrument_and_run_function(lambda_element)
  File "/Users/Ricardo/.pyenv/versions/3.8.20/lib/python3.8/site-packages/sqlalchemy/sql/lambdas.py", line 1199, in _instrument_and_run_function
    self.expr = lambda_element._invoke_user_fn(tracker_instrumented_fn)
  File "/Users/Ricardo/.pyenv/versions/3.8.20/lib/python3.8/site-packages/sqlalchemy/sql/lambdas.py", line 425, in _invoke_user_fn
    return fn()  # type: ignore[no-any-return]
  File "/Users/Ricardo/Documents/Software Development/Fy-yur/app.py", line 407, in shows
    shows_in_db = db.session.execute(select(show)).fetchall()
  File "/Users/Ricardo/.pyenv/versions/3.8.20/lib/python3.8/site-packages/sqlalchemy/sql/lambdas.py", line 1329, in __call__
    raise exc.InvalidRequestError(
sqlalchemy.exc.InvalidRequestError: Can't invoke Python callable execute() inside of lambda expression argument at <code object shows at 0x1022dc710, file "/Users/Ricardo/Documents/Software Development/Fy-yur/app.py", line 404>; lambda SQL constructs should not invoke functions from closure variables to produce literal values since the lambda SQL system normally extracts bound values without actually invoking the lambda or any functions within it.  Call the function outside of the lambda and assign to a local variable that is used in the lambda as a closure variable, or set track_bound_values=False if the return value of this function is used in some other way other than a SQL bound value.
2025-02-24 08:55:48,265 ERROR: Exception on /venues/1 [GET] [in /Users/Ricardo/.pyenv/versions/3.8.20/lib/python3.8/site-packages/flask/app.py:838]
Traceback (most recent call last):
  File "/Users/Ricardo/.pyenv/versions/3.8.20/lib/python3.8/site-packages/flask/app.py", line 1473, in wsgi_app
    response = self.full_dispatch_request()
  File "/Users/Ricardo/.pyenv/versions/3.8.20/lib/python3.8/site-packages/flask/app.py", line 882, in full_dispatch_request
    rv = self.handle_user_exception(e)
  File "/Users/Ricardo/.pyenv/versions/3.8.20/lib/python3.8/site-packages/flask/app.py", line 880, in full_dispatch_request
    rv = self.dispatch_request()
  File "/Users/Ricardo/.pyenv/versions/3.8.20/lib/python3.8/site-packages/flask/app.py", line 865, in dispatch_request
    return self.ensure_sync(self.view_functions[rule.endpoint])(**view_args)  # type: ignore[no-any-return]
  File "/Users/Ricardo/Documents/Software Development/Fy-yur/app.py", line 148, in show_venue
    show_rel = db.session.query(shows).filter_by(venue_id=venue.id, artist_id=artist.id).first()
  File "/Users/Ricardo/.pyenv/versions/3.8.20/lib/python3.8/site-packages/sqlalchemy/orm/scoping.py", line 1681, in query
    return self._proxied.query(*entities, **kwargs)
  File "/Users/Ricardo/.pyenv/versions/3.8.20/lib/python3.8/site-packages/sqlalchemy/orm/session.py", line 2955, in query
    return self._query_cls(entities, self, **kwargs)
  File "/Users/Ricardo/.pyenv/versions/3.8.20/lib/python3.8/site-packages/sqlalchemy/orm/query.py", line 275, in __init__
    self._set_entities(entities)
  File "/Users/Ricardo/.pyenv/versions/3.8.20/lib/python3.8/site-packages/sqlalchemy/orm/query.py", line 287, in _set_entities
    self._raw_columns = [
  File "/Users/Ricardo/.pyenv/versions/3.8.20/lib/python3.8/site-packages/sqlalchemy/orm/query.py", line 288, in <listcomp>
    coercions.expect(
  File "/Users/Ricardo/.pyenv/versions/3.8.20/lib/python3.8/site-packages/sqlalchemy/sql/coercions.py", line 332, in expect
    return lambdas.LambdaElement(
  File "/Users/Ricardo/.pyenv/versions/3.8.20/lib/python3.8/site-packages/sqlalchemy/sql/lambdas.py", line 213, in __init__
    rec = self._retrieve_tracker_rec(fn, apply_propagate_attrs, opts)
  File "/Users/Ricardo/.pyenv/versions/3.8.20/lib/python3.8/site-packages/sqlalchemy/sql/lambdas.py", line 229, in _retrieve_tracker_rec
    tracker = AnalyzedCode.get(
  File "/Users/Ricardo/.pyenv/versions/3.8.20/lib/python3.8/site-packages/sqlalchemy/sql/lambdas.py", line 753, in get
    cls._fns[fn.__code__] = analyzed = AnalyzedCode(
  File "/Users/Ricardo/.pyenv/versions/3.8.20/lib/python3.8/site-packages/sqlalchemy/sql/lambdas.py", line 795, in __init__
    self._setup_additional_closure_trackers(fn, lambda_element, opts)
  File "/Users/Ricardo/.pyenv/versions/3.8.20/lib/python3.8/site-packages/sqlalchemy/sql/lambdas.py", line 863, in _setup_additional_closure_trackers
    analyzed_function = AnalyzedFunction(
  File "/Users/Ricardo/.pyenv/versions/3.8.20/lib/python3.8/site-packages/sqlalchemy/sql/lambdas.py", line 1129, in __init__
    self._instrument_and_run_function(lambda_element)
  File "/Users/Ricardo/.pyenv/versions/3.8.20/lib/python3.8/site-packages/sqlalchemy/sql/lambdas.py", line 1199, in _instrument_and_run_function
    self.expr = lambda_element._invoke_user_fn(tracker_instrumented_fn)
  File "/Users/Ricardo/.pyenv/versions/3.8.20/lib/python3.8/site-packages/sqlalchemy/sql/lambdas.py", line 425, in _invoke_user_fn
    return fn()  # type: ignore[no-any-return]
  File "/Users/Ricardo/Documents/Software Development/Fy-yur/app.py", line 407, in shows
    shows_in_db = db.session.execute(select(show)).fetchall()
  File "/Users/Ricardo/.pyenv/versions/3.8.20/lib/python3.8/site-packages/sqlalchemy/sql/lambdas.py", line 1329, in __call__
    raise exc.InvalidRequestError(
sqlalchemy.exc.InvalidRequestError: Can't invoke Python callable execute() inside of lambda expression argument at <code object shows at 0x1022dc710, file "/Users/Ricardo/Documents/Software Development/Fy-yur/app.py", line 404>; lambda SQL constructs should not invoke functions from closure variables to produce literal values since the lambda SQL system normally extracts bound values without actually invoking the lambda or any functions within it.  Call the function outside of the lambda and assign to a local variable that is used in the lambda as a closure variable, or set track_bound_values=False if the return value of this function is used in some other way other than a SQL bound value.
2025-02-24 08:57:25,339 INFO: errors [in /Users/Ricardo/Documents/Software Development/Fy-yur/app.py:470]
2025-02-24 09:10:26,069 ERROR: Exception on /artists/1 [GET] [in /Users/Ricardo/.pyenv/versions/3.8.20/lib/python3.8/site-packages/flask/app.py:838]
Traceback (most recent call last):
  File "/Users/Ricardo/.pyenv/versions/3.8.20/lib/python3.8/site-packages/flask/app.py", line 1473, in wsgi_app
    response = self.full_dispatch_request()
  File "/Users/Ricardo/.pyenv/versions/3.8.20/lib/python3.8/site-packages/flask/app.py", line 882, in full_dispatch_request
    rv = self.handle_user_exception(e)
  File "/Users/Ricardo/.pyenv/versions/3.8.20/lib/python3.8/site-packages/flask/app.py", line 880, in full_dispatch_request
    rv = self.dispatch_request()
  File "/Users/Ricardo/.pyenv/versions/3.8.20/lib/python3.8/site-packages/flask/app.py", line 865, in dispatch_request
    return self.ensure_sync(self.view_functions[rule.endpoint])(**view_args)  # type: ignore[no-any-return]
  File "/Users/Ricardo/Documents/Software Development/Fy-yur/app.py", line 325, in show_artist
    data = list(filter(lambda d: d['id'] == artist_id, [data1, data2, data3]))[0]
IndexError: list index out of range
2025-02-24 09:10:33,794 ERROR: Exception on /artists/2 [GET] [in /Users/Ricardo/.pyenv/versions/3.8.20/lib/python3.8/site-packages/flask/app.py:838]
Traceback (most recent call last):
  File "/Users/Ricardo/.pyenv/versions/3.8.20/lib/python3.8/site-packages/flask/app.py", line 1473, in wsgi_app
    response = self.full_dispatch_request()
  File "/Users/Ricardo/.pyenv/versions/3.8.20/lib/python3.8/site-packages/flask/app.py", line 882, in full_dispatch_request
    rv = self.handle_user_exception(e)
  File "/Users/Ricardo/.pyenv/versions/3.8.20/lib/python3.8/site-packages/flask/app.py", line 880, in full_dispatch_request
    rv = self.dispatch_request()
  File "/Users/Ricardo/.pyenv/versions/3.8.20/lib/python3.8/site-packages/flask/app.py", line 865, in dispatch_request
    return self.ensure_sync(self.view_functions[rule.endpoint])(**view_args)  # type: ignore[no-any-return]
  File "/Users/Ricardo/Documents/Software Development/Fy-yur/app.py", line 325, in show_artist
    data = list(filter(lambda d: d['id'] == artist_id, [data1, data2, data3]))[0]
IndexError: list index out of range
2025-02-24 09:10:40,191 ERROR: Exception on /artists/1 [GET] [in /Users/Ricardo/.pyenv/versions/3.8.20/lib/python3.8/site-packages/flask/app.py:838]
Traceback (most recent call last):
  File "/Users/Ricardo/.pyenv/versions/3.8.20/lib/python3.8/site-packages/flask/app.py", line 1473, in wsgi_app
    response = self.full_dispatch_request()
  File "/Users/Ricardo/.pyenv/versions/3.8.20/lib/python3.8/site-packages/flask/app.py", line 882, in full_dispatch_request
    rv = self.handle_user_exception(e)
  File "/Users/Ricardo/.pyenv/versions/3.8.20/lib/python3.8/site-packages/flask/app.py", line 880, in full_dispatch_request
    rv = self.dispatch_request()
  File "/Users/Ricardo/.pyenv/versions/3.8.20/lib/python3.8/site-packages/flask/app.py", line 865, in dispatch_request
    return self.ensure_sync(self.view_functions[rule.endpoint])(**view_args)  # type: ignore[no-any-return]
  File "/Users/Ricardo/Documents/Software Development/Fy-yur/app.py", line 325, in show_artist
    data = list(filter(lambda d: d['id'] == artist_id, [data1, data2, data3]))[0]
IndexError: list index out of range
2025-02-24 09:19:36,762 INFO: errors [in /Users/Ricardo/Documents/Software Development/Fy-yur/app.py:468]
2025-02-24 09:19:43,698 INFO: errors [in /Users/Ricardo/Documents/Software Development/Fy-yur/app.py:468]
2025-02-24 09:20:56,194 INFO: errors [in /Users/Ricardo/Documents/Software Development/Fy-yur/app.py:468]
2025-02-24 09:21:43,451 INFO: errors [in /Users/Ricardo/Documents/Software Development/Fy-yur/app.py:468]
2025-02-24 09:21:56,848 INFO: errors [in /Users/Ricardo/Documents/Software Development/Fy-yur/app.py:468]
2025-02-24 09:22:00,829 INFO: errors [in /Users/Ricardo/Documents/Software Development/Fy-yur/app.py:468]
2025-02-24 09:22:08,383 INFO: errors [in /Users/Ricardo/Documents/Software Development/Fy-yur/app.py:468]
2025-02-24 09:22:33,311 INFO: errors [in /Users/Ricardo/Documents/Software Development/Fy-yur/app.py:468]
2025-02-24 09:22:39,953 INFO: errors [in /Users/Ricardo/Documents/Software Development/Fy-yur/app.py:468]
2025-02-24 09:27:29,483 INFO: errors [in /Users/Ricardo/Documents/Software Development/Fy-yur/app.py:468]
2025-02-24 09:35:26,259 ERROR: Exception on /artists/3 [GET] [in /Users/Ricardo/.pyenv/versions/3.8.20/lib/python3.8/site-packages/flask/app.py:838]
Traceback (most recent call last):
  File "/Users/Ricardo/.pyenv/versions/3.8.20/lib/python3.8/site-packages/flask/app.py", line 1473, in wsgi_app
    response = self.full_dispatch_request()
  File "/Users/Ricardo/.pyenv/versions/3.8.20/lib/python3.8/site-packages/flask/app.py", line 882, in full_dispatch_request
    rv = self.handle_user_exception(e)
  File "/Users/Ricardo/.pyenv/versions/3.8.20/lib/python3.8/site-packages/flask/app.py", line 880, in full_dispatch_request
    rv = self.dispatch_request()
  File "/Users/Ricardo/.pyenv/versions/3.8.20/lib/python3.8/site-packages/flask/app.py", line 865, in dispatch_request
    return self.ensure_sync(self.view_functions[rule.endpoint])(**view_args)  # type: ignore[no-any-return]
  File "/Users/Ricardo/Documents/Software Development/Fy-yur/app.py", line 325, in show_artist
IndexError: list index out of range
2025-02-24 09:55:16,491 INFO: errors [in /Users/Ricardo/Documents/Software Development/Fy-yur/app.py:440]
2025-02-24 09:58:36,840 INFO: errors [in /Users/Ricardo/Documents/Software Development/Fy-yur/app.py:440]
2025-02-24 09:58:42,739 ERROR: Exception on /artists/3 [GET] [in /Users/Ricardo/.pyenv/versions/3.8.20/lib/python3.8/site-packages/flask/app.py:838]
Traceback (most recent call last):
  File "/Users/Ricardo/.pyenv/versions/3.8.20/lib/python3.8/site-packages/flask/app.py", line 1473, in wsgi_app
    response = self.full_dispatch_request()
  File "/Users/Ricardo/.pyenv/versions/3.8.20/lib/python3.8/site-packages/flask/app.py", line 882, in full_dispatch_request
    rv = self.handle_user_exception(e)
  File "/Users/Ricardo/.pyenv/versions/3.8.20/lib/python3.8/site-packages/flask/app.py", line 880, in full_dispatch_request
    rv = self.dispatch_request()
  File "/Users/Ricardo/.pyenv/versions/3.8.20/lib/python3.8/site-packages/flask/app.py", line 865, in dispatch_request
    return self.ensure_sync(self.view_functions[rule.endpoint])(**view_args)  # type: ignore[no-any-return]
  File "/Users/Ricardo/Documents/Software Development/Fy-yur/app.py", line 295, in show_artist
    data = list(filter(lambda d: d['id'] == artist_id, data))[0]
IndexError: list index out of range
2025-02-24 09:59:04,675 ERROR: Exception on /artists/4 [GET] [in /Users/Ricardo/.pyenv/versions/3.8.20/lib/python3.8/site-packages/flask/app.py:838]
Traceback (most recent call last):
  File "/Users/Ricardo/.pyenv/versions/3.8.20/lib/python3.8/site-packages/flask/app.py", line 1473, in wsgi_app
    response = self.full_dispatch_request()
  File "/Users/Ricardo/.pyenv/versions/3.8.20/lib/python3.8/site-packages/flask/app.py", line 882, in full_dispatch_request
    rv = self.handle_user_exception(e)
  File "/Users/Ricardo/.pyenv/versions/3.8.20/lib/python3.8/site-packages/flask/app.py", line 880, in full_dispatch_request
    rv = self.dispatch_request()
  File "/Users/Ricardo/.pyenv/versions/3.8.20/lib/python3.8/site-packages/flask/app.py", line 865, in dispatch_request
    return self.ensure_sync(self.view_functions[rule.endpoint])(**view_args)  # type: ignore[no-any-return]
  File "/Users/Ricardo/Documents/Software Development/Fy-yur/app.py", line 295, in show_artist
    data = list(filter(lambda d: d['id'] == artist_id, data))[0]
IndexError: list index out of range
2025-02-24 09:59:08,076 ERROR: Exception on /artists/3 [GET] [in /Users/Ricardo/.pyenv/versions/3.8.20/lib/python3.8/site-packages/flask/app.py:838]
Traceback (most recent call last):
  File "/Users/Ricardo/.pyenv/versions/3.8.20/lib/python3.8/site-packages/flask/app.py", line 1473, in wsgi_app
    response = self.full_dispatch_request()
  File "/Users/Ricardo/.pyenv/versions/3.8.20/lib/python3.8/site-packages/flask/app.py", line 882, in full_dispatch_request
    rv = self.handle_user_exception(e)
  File "/Users/Ricardo/.pyenv/versions/3.8.20/lib/python3.8/site-packages/flask/app.py", line 880, in full_dispatch_request
    rv = self.dispatch_request()
  File "/Users/Ricardo/.pyenv/versions/3.8.20/lib/python3.8/site-packages/flask/app.py", line 865, in dispatch_request
    return self.ensure_sync(self.view_functions[rule.endpoint])(**view_args)  # type: ignore[no-any-return]
  File "/Users/Ricardo/Documents/Software Development/Fy-yur/app.py", line 295, in show_artist
    data = list(filter(lambda d: d['id'] == artist_id, data))[0]
IndexError: list index out of range
2025-02-24 10:02:54,328 ERROR: Exception on /artists/4 [GET] [in /Users/Ricardo/.pyenv/versions/3.8.20/lib/python3.8/site-packages/flask/app.py:838]
Traceback (most recent call last):
  File "/Users/Ricardo/.pyenv/versions/3.8.20/lib/python3.8/site-packages/flask/app.py", line 1473, in wsgi_app
    response = self.full_dispatch_request()
  File "/Users/Ricardo/.pyenv/versions/3.8.20/lib/python3.8/site-packages/flask/app.py", line 882, in full_dispatch_request
    rv = self.handle_user_exception(e)
  File "/Users/Ricardo/.pyenv/versions/3.8.20/lib/python3.8/site-packages/flask/app.py", line 880, in full_dispatch_request
    rv = self.dispatch_request()
  File "/Users/Ricardo/.pyenv/versions/3.8.20/lib/python3.8/site-packages/flask/app.py", line 865, in dispatch_request
    return self.ensure_sync(self.view_functions[rule.endpoint])(**view_args)  # type: ignore[no-any-return]
  File "/Users/Ricardo/Documents/Software Development/Fy-yur/app.py", line 295, in show_artist
    data = list(filter(lambda d: d['id'] == artist_id, data))[0]
IndexError: list index out of range
2025-02-24 10:04:24,607 ERROR: Exception on /artists/4 [GET] [in /Users/Ricardo/.pyenv/versions/3.8.20/lib/python3.8/site-packages/flask/app.py:838]
Traceback (most recent call last):
  File "/Users/Ricardo/.pyenv/versions/3.8.20/lib/python3.8/site-packages/flask/app.py", line 1473, in wsgi_app
    response = self.full_dispatch_request()
  File "/Users/Ricardo/.pyenv/versions/3.8.20/lib/python3.8/site-packages/flask/app.py", line 882, in full_dispatch_request
    rv = self.handle_user_exception(e)
  File "/Users/Ricardo/.pyenv/versions/3.8.20/lib/python3.8/site-packages/flask/app.py", line 880, in full_dispatch_request
    rv = self.dispatch_request()
  File "/Users/Ricardo/.pyenv/versions/3.8.20/lib/python3.8/site-packages/flask/app.py", line 865, in dispatch_request
    return self.ensure_sync(self.view_functions[rule.endpoint])(**view_args)  # type: ignore[no-any-return]
  File "/Users/Ricardo/Documents/Software Development/Fy-yur/app.py", line 295, in show_artist
    data = list(filter(lambda d: d['id'] == artist_id, data))[0]
IndexError: list index out of range
2025-02-24 10:10:27,095 ERROR: Exception on /artists/4 [GET] [in /Users/Ricardo/.pyenv/versions/3.8.20/lib/python3.8/site-packages/flask/app.py:838]
Traceback (most recent call last):
  File "/Users/Ricardo/.pyenv/versions/3.8.20/lib/python3.8/site-packages/flask/app.py", line 1473, in wsgi_app
    response = self.full_dispatch_request()
  File "/Users/Ricardo/.pyenv/versions/3.8.20/lib/python3.8/site-packages/flask/app.py", line 882, in full_dispatch_request
    rv = self.handle_user_exception(e)
  File "/Users/Ricardo/.pyenv/versions/3.8.20/lib/python3.8/site-packages/flask/app.py", line 880, in full_dispatch_request
    rv = self.dispatch_request()
  File "/Users/Ricardo/.pyenv/versions/3.8.20/lib/python3.8/site-packages/flask/app.py", line 865, in dispatch_request
    return self.ensure_sync(self.view_functions[rule.endpoint])(**view_args)  # type: ignore[no-any-return]
  File "/Users/Ricardo/Documents/Software Development/Fy-yur/app.py", line 295, in show_artist
    data = list(filter(lambda d: d['id'] == artist_id, data))[0]
IndexError: list index out of range
2025-02-24 10:10:27,320 ERROR: Exception on /artists/4 [GET] [in /Users/Ricardo/.pyenv/versions/3.8.20/lib/python3.8/site-packages/flask/app.py:838]
Traceback (most recent call last):
  File "/Users/Ricardo/.pyenv/versions/3.8.20/lib/python3.8/site-packages/flask/app.py", line 1473, in wsgi_app
    response = self.full_dispatch_request()
  File "/Users/Ricardo/.pyenv/versions/3.8.20/lib/python3.8/site-packages/flask/app.py", line 882, in full_dispatch_request
    rv = self.handle_user_exception(e)
  File "/Users/Ricardo/.pyenv/versions/3.8.20/lib/python3.8/site-packages/flask/app.py", line 880, in full_dispatch_request
    rv = self.dispatch_request()
  File "/Users/Ricardo/.pyenv/versions/3.8.20/lib/python3.8/site-packages/flask/app.py", line 865, in dispatch_request
    return self.ensure_sync(self.view_functions[rule.endpoint])(**view_args)  # type: ignore[no-any-return]
  File "/Users/Ricardo/Documents/Software Development/Fy-yur/app.py", line 295, in show_artist
    data = list(filter(lambda d: d['id'] == artist_id, data))[0]
IndexError: list index out of range
2025-02-24 10:13:43,455 INFO: errors [in /Users/Ricardo/Documents/Software Development/Fy-yur/app.py:440]
2025-02-24 11:17:03,647 INFO: errors [in /Users/Ricardo/Documents/Software Development/Fy-yur/app.py:486]
2025-02-24 11:19:56,566 INFO: errors [in /Users/Ricardo/Documents/Software Development/Fy-yur/app.py:486]
2025-02-24 11:24:10,369 INFO: errors [in /Users/Ricardo/Documents/Software Development/Fy-yur/app.py:486]
2025-02-24 11:25:13,108 INFO: errors [in /Users/Ricardo/Documents/Software Development/Fy-yur/app.py:486]
2025-02-24 11:27:13,782 INFO: errors [in /Users/Ricardo/Documents/Software Development/Fy-yur/app.py:486]
2025-02-24 11:27:23,734 INFO: errors [in /Users/Ricardo/Documents/Software Development/Fy-yur/app.py:486]
2025-02-24 11:27:31,514 INFO: errors [in /Users/Ricardo/Documents/Software Development/Fy-yur/app.py:486]
2025-02-24 11:40:31,458 INFO: errors [in /Users/Ricardo/Documents/Software Development/Fy-yur/app.py:516]
2025-02-24 11:41:03,186 INFO: errors [in /Users/Ricardo/Documents/Software Development/Fy-yur/app.py:516]
2025-02-24 11:55:28,699 INFO: errors [in /Users/Ricardo/Documents/Software Development/Fy-yur/app.py:537]
2025-02-24 11:55:30,691 ERROR: Exception on /shows/create [POST] [in /Users/Ricardo/.pyenv/versions/3.8.20/lib/python3.8/site-packages/flask/app.py:838]
Traceback (most recent call last):
  File "/Users/Ricardo/.pyenv/versions/3.8.20/lib/python3.8/site-packages/flask/app.py", line 1473, in wsgi_app
    response = self.full_dispatch_request()
  File "/Users/Ricardo/.pyenv/versions/3.8.20/lib/python3.8/site-packages/flask/app.py", line 882, in full_dispatch_request
    rv = self.handle_user_exception(e)
  File "/Users/Ricardo/.pyenv/versions/3.8.20/lib/python3.8/site-packages/flask/app.py", line 880, in full_dispatch_request
    rv = self.dispatch_request()
  File "/Users/Ricardo/.pyenv/versions/3.8.20/lib/python3.8/site-packages/flask/app.py", line 865, in dispatch_request
    return self.ensure_sync(self.view_functions[rule.endpoint])(**view_args)  # type: ignore[no-any-return]
  File "/Users/Ricardo/Documents/Software Development/Fy-yur/app.py", line 488, in create_show_submission
    @app.route('/shows/create', methods=['POST'])
  File "/Users/Ricardo/.pyenv/versions/3.8.20/lib/python3.8/site-packages/flask/sansio/scaffold.py", line 46, in wrapper_func
    self._check_setup_finished(f_name)
  File "/Users/Ricardo/.pyenv/versions/3.8.20/lib/python3.8/site-packages/flask/sansio/app.py", line 415, in _check_setup_finished
    raise AssertionError(
AssertionError: The setup method 'route' can no longer be called on the application. It has already handled its first request, any changes will not be applied consistently.
Make sure all imports, decorators, functions, etc. needed to set up the application are done before running it.
2025-02-24 11:55:52,109 ERROR: Exception on /shows/create [POST] [in /Users/Ricardo/.pyenv/versions/3.8.20/lib/python3.8/site-packages/flask/app.py:838]
Traceback (most recent call last):
  File "/Users/Ricardo/.pyenv/versions/3.8.20/lib/python3.8/site-packages/flask/app.py", line 1473, in wsgi_app
    response = self.full_dispatch_request()
  File "/Users/Ricardo/.pyenv/versions/3.8.20/lib/python3.8/site-packages/flask/app.py", line 882, in full_dispatch_request
    rv = self.handle_user_exception(e)
  File "/Users/Ricardo/.pyenv/versions/3.8.20/lib/python3.8/site-packages/flask/app.py", line 880, in full_dispatch_request
    rv = self.dispatch_request()
  File "/Users/Ricardo/.pyenv/versions/3.8.20/lib/python3.8/site-packages/flask/app.py", line 865, in dispatch_request
    return self.ensure_sync(self.view_functions[rule.endpoint])(**view_args)  # type: ignore[no-any-return]
  File "/Users/Ricardo/Documents/Software Development/Fy-yur/app.py", line 488, in create_show_submission
    @app.route('/shows/create', methods=['POST'])
  File "/Users/Ricardo/.pyenv/versions/3.8.20/lib/python3.8/site-packages/flask/sansio/scaffold.py", line 46, in wrapper_func
    self._check_setup_finished(f_name)
  File "/Users/Ricardo/.pyenv/versions/3.8.20/lib/python3.8/site-packages/flask/sansio/app.py", line 415, in _check_setup_finished
    raise AssertionError(
AssertionError: The setup method 'route' can no longer be called on the application. It has already handled its first request, any changes will not be applied consistently.
Make sure all imports, decorators, functions, etc. needed to set up the application are done before running it.
2025-02-24 11:56:10,980 INFO: errors [in /Users/Ricardo/Documents/Software Development/Fy-yur/app.py:537]
2025-02-24 11:56:17,595 ERROR: Exception on /shows/create [POST] [in /Users/Ricardo/.pyenv/versions/3.8.20/lib/python3.8/site-packages/flask/app.py:838]
Traceback (most recent call last):
  File "/Users/Ricardo/.pyenv/versions/3.8.20/lib/python3.8/site-packages/flask/app.py", line 1473, in wsgi_app
    response = self.full_dispatch_request()
  File "/Users/Ricardo/.pyenv/versions/3.8.20/lib/python3.8/site-packages/flask/app.py", line 882, in full_dispatch_request
    rv = self.handle_user_exception(e)
  File "/Users/Ricardo/.pyenv/versions/3.8.20/lib/python3.8/site-packages/flask/app.py", line 880, in full_dispatch_request
    rv = self.dispatch_request()
  File "/Users/Ricardo/.pyenv/versions/3.8.20/lib/python3.8/site-packages/flask/app.py", line 865, in dispatch_request
    return self.ensure_sync(self.view_functions[rule.endpoint])(**view_args)  # type: ignore[no-any-return]
  File "/Users/Ricardo/Documents/Software Development/Fy-yur/app.py", line 488, in create_show_submission
    @app.route('/shows/create', methods=['POST'])
  File "/Users/Ricardo/.pyenv/versions/3.8.20/lib/python3.8/site-packages/flask/sansio/scaffold.py", line 46, in wrapper_func
    self._check_setup_finished(f_name)
  File "/Users/Ricardo/.pyenv/versions/3.8.20/lib/python3.8/site-packages/flask/sansio/app.py", line 415, in _check_setup_finished
    raise AssertionError(
AssertionError: The setup method 'route' can no longer be called on the application. It has already handled its first request, any changes will not be applied consistently.
Make sure all imports, decorators, functions, etc. needed to set up the application are done before running it.
2025-02-24 11:58:07,805 INFO: errors [in /Users/Ricardo/Documents/Software Development/Fy-yur/app.py:534]
2025-02-24 11:59:19,500 INFO: errors [in /Users/Ricardo/Documents/Software Development/Fy-yur/app.py:534]
2025-02-24 14:53:29,661 INFO: errors [in /Users/Ricardo/Documents/Software Development/Fy-yur/app.py:598]
2025-02-24 14:55:19,183 INFO: errors [in /Users/Ricardo/Documents/Software Development/Fy-yur/app.py:598]
2025-02-24 14:56:56,502 INFO: errors [in /Users/Ricardo/Documents/Software Development/Fy-yur/app.py:598]
2025-02-24 15:04:11,572 INFO: errors [in /Users/Ricardo/Documents/Software Development/Fy-yur/app.py:601]
2025-02-24 15:04:18,630 ERROR: Exception on /venues/1/edit [GET] [in /Users/Ricardo/.pyenv/versions/3.8.20/lib/python3.8/site-packages/flask/app.py:838]
Traceback (most recent call last):
  File "/Users/Ricardo/.pyenv/versions/3.8.20/lib/python3.8/site-packages/flask/app.py", line 1473, in wsgi_app
    response = self.full_dispatch_request()
  File "/Users/Ricardo/.pyenv/versions/3.8.20/lib/python3.8/site-packages/flask/app.py", line 882, in full_dispatch_request
    rv = self.handle_user_exception(e)
  File "/Users/Ricardo/.pyenv/versions/3.8.20/lib/python3.8/site-packages/flask/app.py", line 880, in full_dispatch_request
    rv = self.dispatch_request()
  File "/Users/Ricardo/.pyenv/versions/3.8.20/lib/python3.8/site-packages/flask/app.py", line 865, in dispatch_request
    return self.ensure_sync(self.view_functions[rule.endpoint])(**view_args)  # type: ignore[no-any-return]
  File "/Users/Ricardo/Documents/Software Development/Fy-yur/app.py", line 441, in edit_venue
    "address" : venue.address,
AttributeError: 'Artist' object has no attribute 'address'
2025-02-24 15:04:55,375 INFO: errors [in /Users/Ricardo/Documents/Software Development/Fy-yur/app.py:601]
2025-02-24 15:16:04,120 INFO: errors [in /Users/Ricardo/Documents/Software Development/Fy-yur/app.py:638]
2025-02-24 21:05:26,652 INFO: errors [in /Users/Ricardo/Documents/Software Development/Fy-yur/app.py:661]
2025-02-24 21:08:46,784 INFO: errors [in /Users/Ricardo/Documents/Software Development/Fy-yur/app.py:673]
2025-02-24 21:09:05,799 INFO: errors [in /Users/Ricardo/Documents/Software Development/Fy-yur/app.py:673]
2025-02-24 21:15:25,364 INFO: errors [in /Users/Ricardo/Documents/Software Development/Fy-yur/app.py:673]
2025-02-24 21:21:24,613 INFO: errors [in /Users/Ricardo/Documents/Software Development/Fy-yur/app.py:673]
2025-02-24 21:23:20,466 INFO: errors [in /Users/Ricardo/Documents/Software Development/Fy-yur/app.py:673]
2025-02-24 22:13:39,932 INFO: errors [in /Users/Ricardo/Documents/Software Development/Fy-yur/app.py:608]
2025-02-24 22:14:50,651 INFO: errors [in /Users/Ricardo/Documents/Software Development/Fy-yur/app.py:608]
2025-02-24 22:15:11,348 INFO: errors [in /Users/Ricardo/Documents/Software Development/Fy-yur/app.py:608]
2025-02-24 22:15:20,911 INFO: errors [in /Users/Ricardo/Documents/Software Development/Fy-yur/app.py:608]
